Workbook

Sheet Portfolio
A1: Portfolio Receivables Tracker ($000s)
A3: Dollar Receivables ($000s)
A4: DPD Bucket | B4: 2007-06 | C4: 2007-07 | D4: 2007-08 | E4: 2007-09 | F4: 2007-10 | G4: 2007-11 | H4: 2007-12 | I4: 2008-01 | J4: 2008-02 | K4: 2008-03 | L4: 2008-04 | M4: 2008-05 | N4: 2008-06 | O4: 2008-07 | P4: 2008-08 | Q4: 2008-09 | R4: 2008-10 | S4: 2008-11 | T4: 2008-12 | U4: 2009-01 | V4: 2009-02 | W4: 2009-03 | X4: 2009-04 | Y4: 2009-05 | Z4: 2009-06 | AA4: 2009-07 | AB4: 2009-08 | AC4: 2009-09 | AD4: 2009-10 | AE4: 2009-11 | AF4: 2009-12 | AG4: 2010-01 | AH4: 2010-02 | AI4: 2010-03 | AJ4: 2010-04 | AK4: 2010-05 | AL4: 2010-06 | AM4: 2010-07 | AN4: 2010-08 | AO4: 2010-09 | AP4: 2010-10 | AQ4: 2010-11 | AR4: 2010-12 | AS4: 2011-01 | AT4: 2011-02 | AU4: 2011-03 | AV4: 2011-04 | AW4: 2011-05 | AX4: 2011-06 | AY4: 2011-07 | AZ4: 2011-08 | BA4: 2011-09 | BB4: 2011-10 | BC4: 2011-11 | BD4: 2011-12 | BE4: 2012-01 | BF4: 2012-02 | BG4: 2012-03 | BH4: 2012-04 | BI4: 2012-05 | BJ4: 2012-06 | BK4: 2012-07 | BL4: 2012-08 | BM4: 2012-09 | BN4: 2012-10 | BO4: 2012-11 | BP4: 2012-12 | BQ4: 2013-01 | BR4: 2013-02 | BS4: 2013-03 | BT4: 2013-04 | BU4: 2013-05 | BV4: 2013-06 | BW4: 2013-07 | BX4: 2013-08 | BY4: 2013-09 | BZ4: 2013-10 | CA4: 2013-11 | CB4: 2013-12 | CC4: 2014-01 | CD4: 2014-02 | CE4: 2014-03 | CF4: 2014-04 | CG4: 2014-05 | CH4: 2014-06 | CI4: 2014-07 | CJ4: 2014-08 | CK4: 2014-09 | CL4: 2014-10 | CM4: 2014-11 | CN4: 2014-12 | CO4: 2015-01 | CP4: 2015-02 | CQ4: 2015-03 | CR4: 2015-04 | CS4: 2015-05 | CT4: 2015-06 | CU4: 2015-07 | CV4: 2015-08 | CW4: 2015-09 | CX4: 2015-10 | CY4: 2015-11 | CZ4: 2015-12 | DA4: 2016-01 | DB4: 2016-02 | DC4: 2016-03 | DD4: 2016-04 | DE4: 2016-05 | DF4: 2016-06 | DG4: 2016-07 | DH4: 2016-08 | DI4: 2016-09 | DJ4: 2016-10 | DK4: 2016-11 | DL4: 2016-12 | DM4: 2017-01 | DN4: 2017-02 | DO4: 2017-03 | DP4: 2017-04 | DQ4: 2017-05 | DR4: 2017-06 | DS4: 2017-07 | DT4: 2017-08 | DU4: 2017-09 | DV4: 2017-10 | DW4: 2017-11 | DX4: 2017-12 | DY4: 2018-01 | DZ4: 2018-02 | EA4: 2018-03 | EB4: 2018-04 | EC4: 2018-05 | ED4: 2018-06 | EE4: 2018-07 | EF4: 2018-08 | EG4: 2018-09 | EH4: 2018-10 | EI4: 2018-11 | EJ4: 2018-12 | EK4: 2019-01 | EL4: 2019-02 | EM4: 2019-03 | EN4: 2019-04 | EO4: 2019-05 | EP4: 2019-06 | EQ4: 2019-07 | ER4: 2019-08 | ES4: 2019-09 | ET4: 2019-10 | EU4: 2019-11 | EV4: 2019-12 | EW4: 2020-01 | EX4: 2020-02 | EY4: 2020-03 | EZ4: 2020-04 | FA4: 2020-05 | FB4: 2020-06 | FC4: 2020-07 | FD4: 2020-08 | FE4: 2020-09 | FF4: 2020-10 | FG4: 2020-11 | FH4: 2020-12 | FI4: 2021-01 | FJ4: 2021-02 | FK4: 2021-03 | FL4: 2021-04 | FM4: 2021-05 | FN4: 2021-06 | FO4: 2021-07 | FP4: 2021-08 | FQ4: 2021-09 | FR4: 2021-10 | FS4: 2021-11 | FT4: 2021-12 | FU4: 2022-01 | FV4: 2022-02 | FW4: 2022-03 | FX4: 2022-04 | FY4: 2022-05 | FZ4: 2022-06 | GA4: 2022-07 | GB4: 2022-08 | GC4: 2022-09 | GD4: 2022-10 | GE4: 2022-11 | GF4: 2022-12 | GG4: 2023-01 | GH4: 2023-02 | GI4: 2023-03 | GJ4: 2023-04 | GK4: 2023-05 | GL4: 2023-06 | GM4: 2023-07 | GN4: 2023-08 | GO4: 2023-09
A5: Current | B5: =('Grade A'!B4+'Grade B'!B4+'Grade C'!B4+'Grade D'!B4+'Grade E'!B4+'Grade F'!B4+'Grade G'!B4)/1000 | C5: =('Grade A'!C4+'Grade B'!C4+'Grade C'!C4+'Grade D'!C4+'Grade E'!C4+'Grade F'!C4+'Grade G'!C4)/1000 | D5: =('Grade A'!D4+'Grade B'!D4+'Grade C'!D4+'Grade D'!D4+'Grade E'!D4+'Grade F'!D4+'Grade G'!D4)/1000 | E5: =('Grade A'!E4+'Grade B'!E4+'Grade C'!E4+'Grade D'!E4+'Grade E'!E4+'Grade F'!E4+'Grade G'!E4)/1000 | F5: =('Grade A'!F4+'Grade B'!F4+'Grade C'!F4+'Grade D'!F4+'Grade E'!F4+'Grade F'!F4+'Grade G'!F4)/1000 | G5: =('Grade A'!G4+'Grade B'!G4+'Grade C'!G4+'Grade D'!G4+'Grade E'!G4+'Grade F'!G4+'Grade G'!G4)/1000 | H5: =('Grade A'!H4+'Grade B'!H4+'Grade C'!H4+'Grade D'!H4+'Grade E'!H4+'Grade F'!H4+'Grade G'!H4)/1000 | I5: =('Grade A'!I4+'Grade B'!I4+'Grade C'!I4+'Grade D'!I4+'Grade E'!I4+'Grade F'!I4+'Grade G'!I4)/1000 | ... GO5: =('Grade A'!GO4+'Grade B'!GO4+'Grade C'!GO4+'Grade D'!GO4+'Grade E'!GO4+'Grade F'!GO4+'Grade G'!GO4)/1000
A6: 30+ | B6: =('Grade A'!B5+'Grade B'!B5+'Grade C'!B5+'Grade D'!B5+'Grade E'!B5+'Grade F'!B5+'Grade G'!B5)/1000 | C6: =('Grade A'!C5+'Grade B'!C5+'Grade C'!C5+'Grade D'!C5+'Grade E'!C5+'Grade F'!C5+'Grade G'!C5)/1000 | D6: =('Grade A'!D5+'Grade B'!D5+'Grade C'!D5+'Grade D'!D5+'Grade E'!D5+'Grade F'!D5+'Grade G'!D5)/1000 | E6: =('Grade A'!E5+'Grade B'!E5+'Grade C'!E5+'Grade D'!E5+'Grade E'!E5+'Grade F'!E5+'Grade G'!E5)/1000 | F6: =('Grade A'!F5+'Grade B'!F5+'Grade C'!F5+'Grade D'!F5+'Grade E'!F5+'Grade F'!F5+'Grade G'!F5)/1000 | G6: =('Grade A'!G5+'Grade B'!G5+'Grade C'!G5+'Grade D'!G5+'Grade E'!G5+'Grade F'!G5+'Grade G'!G5)/1000 | H6: =('Grade A'!H5+'Grade B'!H5+'Grade C'!H5+'Grade D'!H5+'Grade E'!H5+'Grade F'!H5+'Grade G'!H5)/1000 | I6: =('Grade A'!I5+'Grade B'!I5+'Grade C'!I5+'Grade D'!I5+'Grade E'!I5+'Grade F'!I5+'Grade G'!I5)/1000 | ... GO6: =('Grade A'!GO5+'Grade B'!GO5+'Grade C'!GO5+'Grade D'!GO5+'Grade E'!GO5+'Grade F'!GO5+'Grade G'!GO5)/1000
A7: 60+ | B7: =('Grade A'!B6+'Grade B'!B6+'Grade C'!B6+'Grade D'!B6+'Grade E'!B6+'Grade F'!B6+'Grade G'!B6)/1000 | C7: =('Grade A'!C6+'Grade B'!C6+'Grade C'!C6+'Grade D'!C6+'Grade E'!C6+'Grade F'!C6+'Grade G'!C6)/1000 | D7: =('Grade A'!D6+'Grade B'!D6+'Grade C'!D6+'Grade D'!D6+'Grade E'!D6+'Grade F'!D6+'Grade G'!D6)/1000 | E7: =('Grade A'!E6+'Grade B'!E6+'Grade C'!E6+'Grade D'!E6+'Grade E'!E6+'Grade F'!E6+'Grade G'!E6)/1000 | F7: =('Grade A'!F6+'Grade B'!F6+'Grade C'!F6+'Grade D'!F6+'Grade E'!F6+'Grade F'!F6+'Grade G'!F6)/1000 | G7: =('Grade A'!G6+'Grade B'!G6+'Grade C'!G6+'Grade D'!G6+'Grade E'!G6+'Grade F'!G6+'Grade G'!G6)/1000 | H7: =('Grade A'!H6+'Grade B'!H6+'Grade C'!H6+'Grade D'!H6+'Grade E'!H6+'Grade F'!H6+'Grade G'!H6)/1000 | I7: =('Grade A'!I6+'Grade B'!I6+'Grade C'!I6+'Grade D'!I6+'Grade E'!I6+'Grade F'!I6+'Grade G'!I6)/1000 | ... GO7: =('Grade A'!GO6+'Grade B'!GO6+'Grade C'!GO6+'Grade D'!GO6+'Grade E'!GO6+'Grade F'!GO6+'Grade G'!GO6)/1000
A8: 90+ | B8: =('Grade A'!B7+'Grade B'!B7+'Grade C'!B7+'Grade D'!B7+'Grade E'!B7+'Grade F'!B7+'Grade G'!B7)/1000 | C8: =('Grade A'!C7+'Grade B'!C7+'Grade C'!C7+'Grade D'!C7+'Grade E'!C7+'Grade F'!C7+'Grade G'!C7)/1000 | D8: =('Grade A'!D7+'Grade B'!D7+'Grade C'!D7+'Grade D'!D7+'Grade E'!D7+'Grade F'!D7+'Grade G'!D7)/1000 | E8: =('Grade A'!E7+'Grade B'!E7+'Grade C'!E7+'Grade D'!E7+'Grade E'!E7+'Grade F'!E7+'Grade G'!E7)/1000 | F8: =('Grade A'!F7+'Grade B'!F7+'Grade C'!F7+'Grade D'!F7+'Grade E'!F7+'Grade F'!F7+'Grade G'!F7)/1000 | G8: =('Grade A'!G7+'Grade B'!G7+'Grade C'!G7+'Grade D'!G7+'Grade E'!G7+'Grade F'!G7+'Grade G'!G7)/1000 | H8: =('Grade A'!H7+'Grade B'!H7+'Grade C'!H7+'Grade D'!H7+'Grade E'!H7+'Grade F'!H7+'Grade G'!H7)/1000 | I8: =('Grade A'!I7+'Grade B'!I7+'Grade C'!I7+'Grade D'!I7+'Grade E'!I7+'Grade F'!I7+'Grade G'!I7)/1000 | ... GO8: =('Grade A'!GO7+'Grade B'!GO7+'Grade C'!GO7+'Grade D'!GO7+'Grade E'!GO7+'Grade F'!GO7+'Grade G'!GO7)/1000
A9: 120+ | B9: =('Grade A'!B8+'Grade B'!B8+'Grade C'!B8+'Grade D'!B8+'Grade E'!B8+'Grade F'!B8+'Grade G'!B8)/1000 | C9: =('Grade A'!C8+'Grade B'!C8+'Grade C'!C8+'Grade D'!C8+'Grade E'!C8+'Grade F'!C8+'Grade G'!C8)/1000 | D9: =('Grade A'!D8+'Grade B'!D8+'Grade C'!D8+'Grade D'!D8+'Grade E'!D8+'Grade F'!D8+'Grade G'!D8)/1000 | E9: =('Grade A'!E8+'Grade B'!E8+'Grade C'!E8+'Grade D'!E8+'Grade E'!E8+'Grade F'!E8+'Grade G'!E8)/1000 | F9: =('Grade A'!F8+'Grade B'!F8+'Grade C'!F8+'Grade D'!F8+'Grade E'!F8+'Grade F'!F8+'Grade G'!F8)/1000 | G9: =('Grade A'!G8+'Grade B'!G8+'Grade C'!G8+'Grade D'!G8+'Grade E'!G8+'Grade F'!G8+'Grade G'!G8)/1000 | H9: =('Grade A'!H8+'Grade B'!H8+'Grade C'!H8+'Grade D'!H8+'Grade E'!H8+'Grade F'!H8+'Grade G'!H8)/1000 | I9: =('Grade A'!I8+'Grade B'!I8+'Grade C'!I8+'Grade D'!I8+'Grade E'!I8+'Grade F'!I8+'Grade G'!I8)/1000 | ... GO9: =('Grade A'!GO8+'Grade B'!GO8+'Grade C'!GO8+'Grade D'!GO8+'Grade E'!GO8+'Grade F'!GO8+'Grade G'!GO8)/1000
A10: 150+ | B10: =('Grade A'!B9+'Grade B'!B9+'Grade C'!B9+'Grade D'!B9+'Grade E'!B9+'Grade F'!B9+'Grade G'!B9)/1000 | C10: =('Grade A'!C9+'Grade B'!C9+'Grade C'!C9+'Grade D'!C9+'Grade E'!C9+'Grade F'!C9+'Grade G'!C9)/1000 | D10: =('Grade A'!D9+'Grade B'!D9+'Grade C'!D9+'Grade D'!D9+'Grade E'!D9+'Grade F'!D9+'Grade G'!D9)/1000 | E10: =('Grade A'!E9+'Grade B'!E9+'Grade C'!E9+'Grade D'!E9+'Grade E'!E9+'Grade F'!E9+'Grade G'!E9)/1000 | F10: =('Grade A'!F9+'Grade B'!F9+'Grade C'!F9+'Grade D'!F9+'Grade E'!F9+'Grade F'!F9+'Grade G'!F9)/1000 | G10: =('Grade A'!G9+'Grade B'!G9+'Grade C'!G9+'Grade D'!G9+'Grade E'!G9+'Grade F'!G9+'Grade G'!G9)/1000 | H10: =('Grade A'!H9+'Grade B'!H9+'Grade C'!H9+'Grade D'!H9+'Grade E'!H9+'Grade F'!H9+'Grade G'!H9)/1000 | I10: =('Grade A'!I9+'Grade B'!I9+'Grade C'!I9+'Grade D'!I9+'Grade E'!I9+'Grade F'!I9+'Grade G'!I9)/1000 | ... GO10: =('Grade A'!GO9+'Grade B'!GO9+'Grade C'!GO9+'Grade D'!GO9+'Grade E'!GO9+'Grade F'!GO9+'Grade G'!GO9)/1000
A11: 180+ | B11: =('Grade A'!B10+'Grade B'!B10+'Grade C'!B10+'Grade D'!B10+'Grade E'!B10+'Grade F'!B10+'Grade G'!B10)/1000 | C11: =('Grade A'!C10+'Grade B'!C10+'Grade C'!C10+'Grade D'!C10+'Grade E'!C10+'Grade F'!C10+'Grade G'!C10)/1000 | D11: =('Grade A'!D10+'Grade B'!D10+'Grade C'!D10+'Grade D'!D10+'Grade E'!D10+'Grade F'!D10+'Grade G'!D10)/1000 | E11: =('Grade A'!E10+'Grade B'!E10+'Grade C'!E10+'Grade D'!E10+'Grade E'!E10+'Grade F'!E10+'Grade G'!E10)/1000 | F11: =('Grade A'!F10+'Grade B'!F10+'Grade C'!F10+'Grade D'!F10+'Grade E'!F10+'Grade F'!F10+'Grade G'!F10)/1000 | G11: =('Grade A'!G10+'Grade B'!G10+'Grade C'!G10+'Grade D'!G10+'Grade E'!G10+'Grade F'!G10+'Grade G'!G10)/1000 | H11: =('Grade A'!H10+'Grade B'!H10+'Grade C'!H10+'Grade D'!H10+'Grade E'!H10+'Grade F'!H10+'Grade G'!H10)/1000 | I11: =('Grade A'!I10+'Grade B'!I10+'Grade C'!I10+'Grade D'!I10+'Grade E'!I10+'Grade F'!I10+'Grade G'!I10)/1000 | ... GO11: =('Grade A'!GO10+'Grade B'!GO10+'Grade C'!GO10+'Grade D'!GO10+'Grade E'!GO10+'Grade F'!GO10+'Grade G'!GO10)/1000
A12: GCO | B12: =('Grade A'!B11+'Grade B'!B11+'Grade C'!B11+'Grade D'!B11+'Grade E'!B11+'Grade F'!B11+'Grade G'!B11)/1000 | C12: =('Grade A'!C11+'Grade B'!C11+'Grade C'!C11+'Grade D'!C11+'Grade E'!C11+'Grade F'!C11+'Grade G'!C11)/1000 | D12: =('Grade A'!D11+'Grade B'!D11+'Grade C'!D11+'Grade D'!D11+'Grade E'!D11+'Grade F'!D11+'Grade G'!D11)/1000 | E12: =('Grade A'!E11+'Grade B'!E11+'Grade C'!E11+'Grade D'!E11+'Grade E'!E11+'Grade F'!E11+'Grade G'!E11)/1000 | F12: =('Grade A'!F11+'Grade B'!F11+'Grade C'!F11+'Grade D'!F11+'Grade E'!F11+'Grade F'!F11+'Grade G'!F11)/1000 | G12: =('Grade A'!G11+'Grade B'!G11+'Grade C'!G11+'Grade D'!G11+'Grade E'!G11+'Grade F'!G11+'Grade G'!G11)/1000 | H12: =('Grade A'!H11+'Grade B'!H11+'Grade C'!H11+'Grade D'!H11+'Grade E'!H11+'Grade F'!H11+'Grade G'!H11)/1000 | I12: =('Grade A'!I11+'Grade B'!I11+'Grade C'!I11+'Grade D'!I11+'Grade E'!I11+'Grade F'!I11+'Grade G'!I11)/1000 | ... GO12: =('Grade A'!GO11+'Grade B'!GO11+'Grade C'!GO11+'Grade D'!GO11+'Grade E'!GO11+'Grade F'!GO11+'Grade G'!GO11)/1000
A13: Total | B13: =SUM(B5:B12) | C13: =SUM(C5:C12) | D13: =SUM(D5:D12) | E13: =SUM(E5:E12) | F13: =SUM(F5:F12) | G13: =SUM(G5:G12) | H13: =SUM(H5:H12) | I13: =SUM(I5:I12) | ... GO13: =SUM(GO5:GO12)
A14: Account Count | B14: ='Grade A'!B12+'Grade B'!B12+'Grade C'!B12+'Grade D'!B12+'Grade E'!B12+'Grade F'!B12+'Grade G'!B12 | C14: ='Grade A'!C12+'Grade B'!C12+'Grade C'!C12+'Grade D'!C12+'Grade E'!C12+'Grade F'!C12+'Grade G'!C12 | D14: ='Grade A'!D12+'Grade B'!D12+'Grade C'!D12+'Grade D'!D12+'Grade E'!D12+'Grade F'!D12+'Grade G'!D12 | E14: ='Grade A'!E12+'Grade B'!E12+'Grade C'!E12+'Grade D'!E12+'Grade E'!E12+'Grade F'!E12+'Grade G'!E12 | F14: ='Grade A'!F12+'Grade B'!F12+'Grade C'!F12+'Grade D'!F12+'Grade E'!F12+'Grade F'!F12+'Grade G'!F12 | G14: ='Grade A'!G12+'Grade B'!G12+'Grade C'!G12+'Grade D'!G12+'Grade E'!G12+'Grade F'!G12+'Grade G'!G12 | H14: ='Grade A'!H12+'Grade B'!H12+'Grade C'!H12+'Grade D'!H12+'Grade E'!H12+'Grade F'!H12+'Grade G'!H12 | I14: ='Grade A'!I12+'Grade B'!I12+'Grade C'!I12+'Grade D'!I12+'Grade E'!I12+'Grade F'!I12+'Grade G'!I12 | ... GO14: ='Grade A'!GO12+'Grade B'!GO12+'Grade C'!GO12+'Grade D'!GO12+'Grade E'!GO12+'Grade F'!GO12+'Grade G'!GO12
A16: Wtd Avg Flow Rates (%)
A17: Transition | B17: 2007-06 | C17: 2007-07 | D17: 2007-08 | E17: 2007-09 | F17: 2007-10 | G17: 2007-11 | H17: 2007-12 | I17: 2008-01 | J17: 2008-02 | K17: 2008-03 | L17: 2008-04 | M17: 2008-05 | N17: 2008-06 | O17: 2008-07 | P17: 2008-08 | Q17: 2008-09 | R17: 2008-10 | S17: 2008-11 | T17: 2008-12 | U17: 2009-01 | V17: 2009-02 | W17: 2009-03 | X17: 2009-04 | Y17: 2009-05 | Z17: 2009-06 | AA17: 2009-07 | AB17: 2009-08 | AC17: 2009-09 | AD17: 2009-10 | AE17: 2009-11 | AF17: 2009-12 | AG17: 2010-01 | AH17: 2010-02 | AI17: 2010-03 | AJ17: 2010-04 | AK17: 2010-05 | AL17: 2010-06 | AM17: 2010-07 | AN17: 2010-08 | AO17: 2010-09 | AP17: 2010-10 | AQ17: 2010-11 | AR17: 2010-12 | AS17: 2011-01 | AT17: 2011-02 | AU17: 2011-03 | AV17: 2011-04 | AW17: 2011-05 | AX17: 2011-06 | AY17: 2011-07 | AZ17: 2011-08 | BA17: 2011-09 | BB17: 2011-10 | BC17: 2011-11 | BD17: 2011-12 | BE17: 2012-01 | BF17: 2012-02 | BG17: 2012-03 | BH17: 2012-04 | BI17: 2012-05 | BJ17: 2012-06 | BK17: 2012-07 | BL17: 2012-08 | BM17: 2012-09 | BN17: 2012-10 | BO17: 2012-11 | BP17: 2012-12 | BQ17: 2013-01 | BR17: 2013-02 | BS17: 2013-03 | BT17: 2013-04 | BU17: 2013-05 | BV17: 2013-06 | BW17: 2013-07 | BX17: 2013-08 | BY17: 2013-09 | BZ17: 2013-10 | CA17: 2013-11 | CB17: 2013-12 | CC17: 2014-01 | CD17: 2014-02 | CE17: 2014-03 | CF17: 2014-04 | CG17: 2014-05 | CH17: 2014-06 | CI17: 2014-07 | CJ17: 2014-08 | CK17: 2014-09 | CL17: 2014-10 | CM17: 2014-11 | CN17: 2014-12 | CO17: 2015-01 | CP17: 2015-02 | CQ17: 2015-03 | CR17: 2015-04 | CS17: 2015-05 | CT17: 2015-06 | CU17: 2015-07 | CV17: 2015-08 | CW17: 2015-09 | CX17: 2015-10 | CY17: 2015-11 | CZ17: 2015-12 | DA17: 2016-01 | DB17: 2016-02 | DC17: 2016-03 | DD17: 2016-04 | DE17: 2016-05 | DF17: 2016-06 | DG17: 2016-07 | DH17: 2016-08 | DI17: 2016-09 | DJ17: 2016-10 | DK17: 2016-11 | DL17: 2016-12 | DM17: 2017-01 | DN17: 2017-02 | DO17: 2017-03 | DP17: 2017-04 | DQ17: 2017-05 | DR17: 2017-06 | DS17: 2017-07 | DT17: 2017-08 | DU17: 2017-09 | DV17: 2017-10 | DW17: 2017-11 | DX17: 2017-12 | DY17: 2018-01 | DZ17: 2018-02 | EA17: 2018-03 | EB17: 2018-04 | EC17: 2018-05 | ED17: 2018-06 | EE17: 2018-07 | EF17: 2018-08 | EG17: 2018-09 | EH17: 2018-10 | EI17: 2018-11 | EJ17: 2018-12 | EK17: 2019-01 | EL17: 2019-02 | EM17: 2019-03 | EN17: 2019-04 | EO17: 2019-05 | EP17: 2019-06 | EQ17: 2019-07 | ER17: 2019-08 | ES17: 2019-09 | ET17: 2019-10 | EU17: 2019-11 | EV17: 2019-12 | EW17: 2020-01 | EX17: 2020-02 | EY17: 2020-03 | EZ17: 2020-04 | FA17: 2020-05 | FB17: 2020-06 | FC17: 2020-07 | FD17: 2020-08 | FE17: 2020-09 | FF17: 2020-10 | FG17: 2020-11 | FH17: 2020-12 | FI17: 2021-01 | FJ17: 2021-02 | FK17: 2021-03 | FL17: 2021-04 | FM17: 2021-05 | FN17: 2021-06 | FO17: 2021-07 | FP17: 2021-08 | FQ17: 2021-09 | FR17: 2021-10 | FS17: 2021-11 | FT17: 2021-12 | FU17: 2022-01 | FV17: 2022-02 | FW17: 2022-03 | FX17: 2022-04 | FY17: 2022-05 | FZ17: 2022-06 | GA17: 2022-07 | GB17: 2022-08 | GC17: 2022-09 | GD17: 2022-10 | GE17: 2022-11 | GF17: 2022-12 | GG17: 2023-01 | GH17: 2023-02 | GI17: 2023-03 | GJ17: 2023-04 | GK17: 2023-05 | GL17: 2023-06 | GM17: 2023-07 | GN17: 2023-08 | GO17: 2023-09
A18: 30+ FR | B18: =IFERROR(('Grade A'!B4*'Grade A'!B18+'Grade B'!B4*'Grade B'!B18+'Grade C'!B4*'Grade C'!B18+'Grade D'!B4*'Grade D'!B18+'Grade E'!B4*'Grade E'!B18+'Grade F'!B4*'Grade F'!B18+'Grade G'!B4*'Grade G'!B18)/('Grade A'!B4+'Grade B'!B4+'Grade C'!B4+'Grade D'!B4+'Grade E'!B4+'Grade F'!B4+'Grade G'!B4),0) | C18: =IFERROR(('Grade A'!C4*'Grade A'!C18+'Grade B'!C4*'Grade B'!C18+'Grade C'!C4*'Grade C'!C18+'Grade D'!C4*'Grade D'!C18+'Grade E'!C4*'Grade E'!C18+'Grade F'!C4*'Grade F'!C18+'Grade G'!C4*'Grade G'!C18)/('Grade A'!C4+'Grade B'!C4+'Grade C'!C4+'Grade D'!C4+'Grade E'!C4+'Grade F'!C4+'Grade G'!C4),0) | D18: =IFERROR(('Grade A'!D4*'Grade A'!D18+'Grade B'!D4*'Grade B'!D18+'Grade C'!D4*'Grade C'!D18+'Grade D'!D4*'Grade D'!D18+'Grade E'!D4*'Grade E'!D18+'Grade F'!D4*'Grade F'!D18+'Grade G'!D4*'Grade G'!D18)/('Grade A'!D4+'Grade B'!D4+'Grade C'!D4+'Grade D'!D4+'Grade E'!D4+'Grade F'!D4+'Grade G'!D4),0) | E18: =IFERROR(('Grade A'!E4*'Grade A'!E18+'Grade B'!E4*'Grade B'!E18+'Grade C'!E4*'Grade C'!E18+'Grade D'!E4*'Grade D'!E18+'Grade E'!E4*'Grade E'!E18+'Grade F'!E4*'Grade F'!E18+'Grade G'!E4*'Grade G'!E18)/('Grade A'!E4+'Grade B'!E4+'Grade C'!E4+'Grade D'!E4+'Grade E'!E4+'Grade F'!E4+'Grade G'!E4),0) | F18: =IFERROR(('Grade A'!F4*'Grade A'!F18+'Grade B'!F4*'Grade B'!F18+'Grade C'!F4*'Grade C'!F18+'Grade D'!F4*'Grade D'!F18+'Grade E'!F4*'Grade E'!F18+'Grade F'!F4*'Grade F'!F18+'Grade G'!F4*'Grade G'!F18)/('Grade A'!F4+'Grade B'!F4+'Grade C'!F4+'Grade D'!F4+'Grade E'!F4+'Grade F'!F4+'Grade G'!F4),0) | G18: =IFERROR(('Grade A'!G4*'Grade A'!G18+'Grade B'!G4*'Grade B'!G18+'Grade C'!G4*'Grade C'!G18+'Grade D'!G4*'Grade D'!G18+'Grade E'!G4*'Grade E'!G18+'Grade F'!G4*'Grade F'!G18+'Grade G'!G4*'Grade G'!G18)/('Grade A'!G4+'Grade B'!G4+'Grade C'!G4+'Grade D'!G4+'Grade E'!G4+'Grade F'!G4+'Grade G'!G4),0) | H18: =IFERROR(('Grade A'!H4*'Grade A'!H18+'Grade B'!H4*'Grade B'!H18+'Grade C'!H4*'Grade C'!H18+'Grade D'!H4*'Grade D'!H18+'Grade E'!H4*'Grade E'!H18+'Grade F'!H4*'Grade F'!H18+'Grade G'!H4*'Grade G'!H18)/('Grade A'!H4+'Grade B'!H4+'Grade C'!H4+'Grade D'!H4+'Grade E'!H4+'Grade F'!H4+'Grade G'!H4),0) | I18: =IFERROR(('Grade A'!I4*'Grade A'!I18+'Grade B'!I4*'Grade B'!I18+'Grade C'!I4*'Grade C'!I18+'Grade D'!I4*'Grade D'!I18+'Grade E'!I4*'Grade E'!I18+'Grade F'!I4*'Grade F'!I18+'Grade G'!I4*'Grade G'!I18)/('Grade A'!I4+'Grade B'!I4+'Grade C'!I4+'Grade D'!I4+'Grade E'!I4+'Grade F'!I4+'Grade G'!I4),0) | ... GO18: =IFERROR(('Grade A'!GO4*'Grade A'!GO18+'Grade B'!GO4*'Grade B'!GO18+'Grade C'!GO4*'Grade C'!GO18+'Grade D'!GO4*'Grade D'!GO18+'Grade E'!GO4*'Grade E'!GO18+'Grade F'!GO4*'Grade F'!GO18+'Grade G'!GO4*'Grade G'!GO18)/('Grade A'!GO4+'Grade B'!GO4+'Grade C'!GO4+'Grade D'!GO4+'Grade E'!GO4+'Grade F'!GO4+'Grade G'!GO4),0)
A19: 60+ FR | B19: =IFERROR(('Grade A'!B5*'Grade A'!B19+'Grade B'!B5*'Grade B'!B19+'Grade C'!B5*'Grade C'!B19+'Grade D'!B5*'Grade D'!B19+'Grade E'!B5*'Grade E'!B19+'Grade F'!B5*'Grade F'!B19+'Grade G'!B5*'Grade G'!B19)/('Grade A'!B5+'Grade B'!B5+'Grade C'!B5+'Grade D'!B5+'Grade E'!B5+'Grade F'!B5+'Grade G'!B5),0) | C19: =IFERROR(('Grade A'!C5*'Grade A'!C19+'Grade B'!C5*'Grade B'!C19+'Grade C'!C5*'Grade C'!C19+'Grade D'!C5*'Grade D'!C19+'Grade E'!C5*'Grade E'!C19+'Grade F'!C5*'Grade F'!C19+'Grade G'!C5*'Grade G'!C19)/('Grade A'!C5+'Grade B'!C5+'Grade C'!C5+'Grade D'!C5+'Grade E'!C5+'Grade F'!C5+'Grade G'!C5),0) | D19: =IFERROR(('Grade A'!D5*'Grade A'!D19+'Grade B'!D5*'Grade B'!D19+'Grade C'!D5*'Grade C'!D19+'Grade D'!D5*'Grade D'!D19+'Grade E'!D5*'Grade E'!D19+'Grade F'!D5*'Grade F'!D19+'Grade G'!D5*'Grade G'!D19)/('Grade A'!D5+'Grade B'!D5+'Grade C'!D5+'Grade D'!D5+'Grade E'!D5+'Grade F'!D5+'Grade G'!D5),0) | E19: =IFERROR(('Grade A'!E5*'Grade A'!E19+'Grade B'!E5*'Grade B'!E19+'Grade C'!E5*'Grade C'!E19+'Grade D'!E5*'Grade D'!E19+'Grade E'!E5*'Grade E'!E19+'Grade F'!E5*'Grade F'!E19+'Grade G'!E5*'Grade G'!E19)/('Grade A'!E5+'Grade B'!E5+'Grade C'!E5+'Grade D'!E5+'Grade E'!E5+'Grade F'!E5+'Grade G'!E5),0) | F19: =IFERROR(('Grade A'!F5*'Grade A'!F19+'Grade B'!F5*'Grade B'!F19+'Grade C'!F5*'Grade C'!F19+'Grade D'!F5*'Grade D'!F19+'Grade E'!F5*'Grade E'!F19+'Grade F'!F5*'Grade F'!F19+'Grade G'!F5*'Grade G'!F19)/('Grade A'!F5+'Grade B'!F5+'Grade C'!F5+'Grade D'!F5+'Grade E'!F5+'Grade F'!F5+'Grade G'!F5),0) | G19: =IFERROR(('Grade A'!G5*'Grade A'!G19+'Grade B'!G5*'Grade B'!G19+'Grade C'!G5*'Grade C'!G19+'Grade D'!G5*'Grade D'!G19+'Grade E'!G5*'Grade E'!G19+'Grade F'!G5*'Grade F'!G19+'Grade G'!G5*'Grade G'!G19)/('Grade A'!G5+'Grade B'!G5+'Grade C'!G5+'Grade D'!G5+'Grade E'!G5+'Grade F'!G5+'Grade G'!G5),0) | H19: =IFERROR(('Grade A'!H5*'Grade A'!H19+'Grade B'!H5*'Grade B'!H19+'Grade C'!H5*'Grade C'!H19+'Grade D'!H5*'Grade D'!H19+'Grade E'!H5*'Grade E'!H19+'Grade F'!H5*'Grade F'!H19+'Grade G'!H5*'Grade G'!H19)/('Grade A'!H5+'Grade B'!H5+'Grade C'!H5+'Grade D'!H5+'Grade E'!H5+'Grade F'!H5+'Grade G'!H5),0) | I19: =IFERROR(('Grade A'!I5*'Grade A'!I19+'Grade B'!I5*'Grade B'!I19+'Grade C'!I5*'Grade C'!I19+'Grade D'!I5*'Grade D'!I19+'Grade E'!I5*'Grade E'!I19+'Grade F'!I5*'Grade F'!I19+'Grade G'!I5*'Grade G'!I19)/('Grade A'!I5+'Grade B'!I5+'Grade C'!I5+'Grade D'!I5+'Grade E'!I5+'Grade F'!I5+'Grade G'!I5),0) | ... GO19: =IFERROR(('Grade A'!GO5*'Grade A'!GO19+'Grade B'!GO5*'Grade B'!GO19+'Grade C'!GO5*'Grade C'!GO19+'Grade D'!GO5*'Grade D'!GO19+'Grade E'!GO5*'Grade E'!GO19+'Grade F'!GO5*'Grade F'!GO19+'Grade G'!GO5*'Grade G'!GO19)/('Grade A'!GO5+'Grade B'!GO5+'Grade C'!GO5+'Grade D'!GO5+'Grade E'!GO5+'Grade F'!GO5+'Grade G'!GO5),0)
A20: 90+ FR | B20: =IFERROR(('Grade A'!B6*'Grade A'!B20+'Grade B'!B6*'Grade B'!B20+'Grade C'!B6*'Grade C'!B20+'Grade D'!B6*'Grade D'!B20+'Grade E'!B6*'Grade E'!B20+'Grade F'!B6*'Grade F'!B20+'Grade G'!B6*'Grade G'!B20)/('Grade A'!B6+'Grade B'!B6+'Grade C'!B6+'Grade D'!B6+'Grade E'!B6+'Grade F'!B6+'Grade G'!B6),0) | C20: =IFERROR(('Grade A'!C6*'Grade A'!C20+'Grade B'!C6*'Grade B'!C20+'Grade C'!C6*'Grade C'!C20+'Grade D'!C6*'Grade D'!C20+'Grade E'!C6*'Grade E'!C20+'Grade F'!C6*'Grade F'!C20+'Grade G'!C6*'Grade G'!C20)/('Grade A'!C6+'Grade B'!C6+'Grade C'!C6+'Grade D'!C6+'Grade E'!C6+'Grade F'!C6+'Grade G'!C6),0) | D20: =IFERROR(('Grade A'!D6*'Grade A'!D20+'Grade B'!D6*'Grade B'!D20+'Grade C'!D6*'Grade C'!D20+'Grade D'!D6*'Grade D'!D20+'Grade E'!D6*'Grade E'!D20+'Grade F'!D6*'Grade F'!D20+'Grade G'!D6*'Grade G'!D20)/('Grade A'!D6+'Grade B'!D6+'Grade C'!D6+'Grade D'!D6+'Grade E'!D6+'Grade F'!D6+'Grade G'!D6),0) | E20: =IFERROR(('Grade A'!E6*'Grade A'!E20+'Grade B'!E6*'Grade B'!E20+'Grade C'!E6*'Grade C'!E20+'Grade D'!E6*'Grade D'!E20+'Grade E'!E6*'Grade E'!E20+'Grade F'!E6*'Grade F'!E20+'Grade G'!E6*'Grade G'!E20)/('Grade A'!E6+'Grade B'!E6+'Grade C'!E6+'Grade D'!E6+'Grade E'!E6+'Grade F'!E6+'Grade G'!E6),0) | F20: =IFERROR(('Grade A'!F6*'Grade A'!F20+'Grade B'!F6*'Grade B'!F20+'Grade C'!F6*'Grade C'!F20+'Grade D'!F6*'Grade D'!F20+'Grade E'!F6*'Grade E'!F20+'Grade F'!F6*'Grade F'!F20+'Grade G'!F6*'Grade G'!F20)/('Grade A'!F6+'Grade B'!F6+'Grade C'!F6+'Grade D'!F6+'Grade E'!F6+'Grade F'!F6+'Grade G'!F6),0) | G20: =IFERROR(('Grade A'!G6*'Grade A'!G20+'Grade B'!G6*'Grade B'!G20+'Grade C'!G6*'Grade C'!G20+'Grade D'!G6*'Grade D'!G20+'Grade E'!G6*'Grade E'!G20+'Grade F'!G6*'Grade F'!G20+'Grade G'!G6*'Grade G'!G20)/('Grade A'!G6+'Grade B'!G6+'Grade C'!G6+'Grade D'!G6+'Grade E'!G6+'Grade F'!G6+'Grade G'!G6),0) | H20: =IFERROR(('Grade A'!H6*'Grade A'!H20+'Grade B'!H6*'Grade B'!H20+'Grade C'!H6*'Grade C'!H20+'Grade D'!H6*'Grade D'!H20+'Grade E'!H6*'Grade E'!H20+'Grade F'!H6*'Grade F'!H20+'Grade G'!H6*'Grade G'!H20)/('Grade A'!H6+'Grade B'!H6+'Grade C'!H6+'Grade D'!H6+'Grade E'!H6+'Grade F'!H6+'Grade G'!H6),0) | I20: =IFERROR(('Grade A'!I6*'Grade A'!I20+'Grade B'!I6*'Grade B'!I20+'Grade C'!I6*'Grade C'!I20+'Grade D'!I6*'Grade D'!I20+'Grade E'!I6*'Grade E'!I20+'Grade F'!I6*'Grade F'!I20+'Grade G'!I6*'Grade G'!I20)/('Grade A'!I6+'Grade B'!I6+'Grade C'!I6+'Grade D'!I6+'Grade E'!I6+'Grade F'!I6+'Grade G'!I6),0) | ... GO20: =IFERROR(('Grade A'!GO6*'Grade A'!GO20+'Grade B'!GO6*'Grade B'!GO20+'Grade C'!GO6*'Grade C'!GO20+'Grade D'!GO6*'Grade D'!GO20+'Grade E'!GO6*'Grade E'!GO20+'Grade F'!GO6*'Grade F'!GO20+'Grade G'!GO6*'Grade G'!GO20)/('Grade A'!GO6+'Grade B'!GO6+'Grade C'!GO6+'Grade D'!GO6+'Grade E'!GO6+'Grade F'!GO6+'Grade G'!GO6),0)
A21: 120+ FR | B21: =IFERROR(('Grade A'!B7*'Grade A'!B21+'Grade B'!B7*'Grade B'!B21+'Grade C'!B7*'Grade C'!B21+'Grade D'!B7*'Grade D'!B21+'Grade E'!B7*'Grade E'!B21+'Grade F'!B7*'Grade F'!B21+'Grade G'!B7*'Grade G'!B21)/('Grade A'!B7+'Grade B'!B7+'Grade C'!B7+'Grade D'!B7+'Grade E'!B7+'Grade F'!B7+'Grade G'!B7),0) | C21: =IFERROR(('Grade A'!C7*'Grade A'!C21+'Grade B'!C7*'Grade B'!C21+'Grade C'!C7*'Grade C'!C21+'Grade D'!C7*'Grade D'!C21+'Grade E'!C7*'Grade E'!C21+'Grade F'!C7*'Grade F'!C21+'Grade G'!C7*'Grade G'!C21)/('Grade A'!C7+'Grade B'!C7+'Grade C'!C7+'Grade D'!C7+'Grade E'!C7+'Grade F'!C7+'Grade G'!C7),0) | D21: =IFERROR(('Grade A'!D7*'Grade A'!D21+'Grade B'!D7*'Grade B'!D21+'Grade C'!D7*'Grade C'!D21+'Grade D'!D7*'Grade D'!D21+'Grade E'!D7*'Grade E'!D21+'Grade F'!D7*'Grade F'!D21+'Grade G'!D7*'Grade G'!D21)/('Grade A'!D7+'Grade B'!D7+'Grade C'!D7+'Grade D'!D7+'Grade E'!D7+'Grade F'!D7+'Grade G'!D7),0) | E21: =IFERROR(('Grade A'!E7*'Grade A'!E21+'Grade B'!E7*'Grade B'!E21+'Grade C'!E7*'Grade C'!E21+'Grade D'!E7*'Grade D'!E21+'Grade E'!E7*'Grade E'!E21+'Grade F'!E7*'Grade F'!E21+'Grade G'!E7*'Grade G'!E21)/('Grade A'!E7+'Grade B'!E7+'Grade C'!E7+'Grade D'!E7+'Grade E'!E7+'Grade F'!E7+'Grade G'!E7),0) | F21: =IFERROR(('Grade A'!F7*'Grade A'!F21+'Grade B'!F7*'Grade B'!F21+'Grade C'!F7*'Grade C'!F21+'Grade D'!F7*'Grade D'!F21+'Grade E'!F7*'Grade E'!F21+'Grade F'!F7*'Grade F'!F21+'Grade G'!F7*'Grade G'!F21)/('Grade A'!F7+'Grade B'!F7+'Grade C'!F7+'Grade D'!F7+'Grade E'!F7+'Grade F'!F7+'Grade G'!F7),0) | G21: =IFERROR(('Grade A'!G7*'Grade A'!G21+'Grade B'!G7*'Grade B'!G21+'Grade C'!G7*'Grade C'!G21+'Grade D'!G7*'Grade D'!G21+'Grade E'!G7*'Grade E'!G21+'Grade F'!G7*'Grade F'!G21+'Grade G'!G7*'Grade G'!G21)/('Grade A'!G7+'Grade B'!G7+'Grade C'!G7+'Grade D'!G7+'Grade E'!G7+'Grade F'!G7+'Grade G'!G7),0) | H21: =IFERROR(('Grade A'!H7*'Grade A'!H21+'Grade B'!H7*'Grade B'!H21+'Grade C'!H7*'Grade C'!H21+'Grade D'!H7*'Grade D'!H21+'Grade E'!H7*'Grade E'!H21+'Grade F'!H7*'Grade F'!H21+'Grade G'!H7*'Grade G'!H21)/('Grade A'!H7+'Grade B'!H7+'Grade C'!H7+'Grade D'!H7+'Grade E'!H7+'Grade F'!H7+'Grade G'!H7),0) | I21: =IFERROR(('Grade A'!I7*'Grade A'!I21+'Grade B'!I7*'Grade B'!I21+'Grade C'!I7*'Grade C'!I21+'Grade D'!I7*'Grade D'!I21+'Grade E'!I7*'Grade E'!I21+'Grade F'!I7*'Grade F'!I21+'Grade G'!I7*'Grade G'!I21)/('Grade A'!I7+'Grade B'!I7+'Grade C'!I7+'Grade D'!I7+'Grade E'!I7+'Grade F'!I7+'Grade G'!I7),0) | ... GO21: =IFERROR(('Grade A'!GO7*'Grade A'!GO21+'Grade B'!GO7*'Grade B'!GO21+'Grade C'!GO7*'Grade C'!GO21+'Grade D'!GO7*'Grade D'!GO21+'Grade E'!GO7*'Grade E'!GO21+'Grade F'!GO7*'Grade F'!GO21+'Grade G'!GO7*'Grade G'!GO21)/('Grade A'!GO7+'Grade B'!GO7+'Grade C'!GO7+'Grade D'!GO7+'Grade E'!GO7+'Grade F'!GO7+'Grade G'!GO7),0)
A22: 150+ FR | B22: =IFERROR(('Grade A'!B8*'Grade A'!B22+'Grade B'!B8*'Grade B'!B22+'Grade C'!B8*'Grade C'!B22+'Grade D'!B8*'Grade D'!B22+'Grade E'!B8*'Grade E'!B22+'Grade F'!B8*'Grade F'!B22+'Grade G'!B8*'Grade G'!B22)/('Grade A'!B8+'Grade B'!B8+'Grade C'!B8+'Grade D'!B8+'Grade E'!B8+'Grade F'!B8+'Grade G'!B8),0) | C22: =IFERROR(('Grade A'!C8*'Grade A'!C22+'Grade B'!C8*'Grade B'!C22+'Grade C'!C8*'Grade C'!C22+'Grade D'!C8*'Grade D'!C22+'Grade E'!C8*'Grade E'!C22+'Grade F'!C8*'Grade F'!C22+'Grade G'!C8*'Grade G'!C22)/('Grade A'!C8+'Grade B'!C8+'Grade C'!C8+'Grade D'!C8+'Grade E'!C8+'Grade F'!C8+'Grade G'!C8),0) | D22: =IFERROR(('Grade A'!D8*'Grade A'!D22+'Grade B'!D8*'Grade B'!D22+'Grade C'!D8*'Grade C'!D22+'Grade D'!D8*'Grade D'!D22+'Grade E'!D8*'Grade E'!D22+'Grade F'!D8*'Grade F'!D22+'Grade G'!D8*'Grade G'!D22)/('Grade A'!D8+'Grade B'!D8+'Grade C'!D8+'Grade D'!D8+'Grade E'!D8+'Grade F'!D8+'Grade G'!D8),0) | E22: =IFERROR(('Grade A'!E8*'Grade A'!E22+'Grade B'!E8*'Grade B'!E22+'Grade C'!E8*'Grade C'!E22+'Grade D'!E8*'Grade D'!E22+'Grade E'!E8*'Grade E'!E22+'Grade F'!E8*'Grade F'!E22+'Grade G'!E8*'Grade G'!E22)/('Grade A'!E8+'Grade B'!E8+'Grade C'!E8+'Grade D'!E8+'Grade E'!E8+'Grade F'!E8+'Grade G'!E8),0) | F22: =IFERROR(('Grade A'!F8*'Grade A'!F22+'Grade B'!F8*'Grade B'!F22+'Grade C'!F8*'Grade C'!F22+'Grade D'!F8*'Grade D'!F22+'Grade E'!F8*'Grade E'!F22+'Grade F'!F8*'Grade F'!F22+'Grade G'!F8*'Grade G'!F22)/('Grade A'!F8+'Grade B'!F8+'Grade C'!F8+'Grade D'!F8+'Grade E'!F8+'Grade F'!F8+'Grade G'!F8),0) | G22: =IFERROR(('Grade A'!G8*'Grade A'!G22+'Grade B'!G8*'Grade B'!G22+'Grade C'!G8*'Grade C'!G22+'Grade D'!G8*'Grade D'!G22+'Grade E'!G8*'Grade E'!G22+'Grade F'!G8*'Grade F'!G22+'Grade G'!G8*'Grade G'!G22)/('Grade A'!G8+'Grade B'!G8+'Grade C'!G8+'Grade D'!G8+'Grade E'!G8+'Grade F'!G8+'Grade G'!G8),0) | H22: =IFERROR(('Grade A'!H8*'Grade A'!H22+'Grade B'!H8*'Grade B'!H22+'Grade C'!H8*'Grade C'!H22+'Grade D'!H8*'Grade D'!H22+'Grade E'!H8*'Grade E'!H22+'Grade F'!H8*'Grade F'!H22+'Grade G'!H8*'Grade G'!H22)/('Grade A'!H8+'Grade B'!H8+'Grade C'!H8+'Grade D'!H8+'Grade E'!H8+'Grade F'!H8+'Grade G'!H8),0) | I22: =IFERROR(('Grade A'!I8*'Grade A'!I22+'Grade B'!I8*'Grade B'!I22+'Grade C'!I8*'Grade C'!I22+'Grade D'!I8*'Grade D'!I22+'Grade E'!I8*'Grade E'!I22+'Grade F'!I8*'Grade F'!I22+'Grade G'!I8*'Grade G'!I22)/('Grade A'!I8+'Grade B'!I8+'Grade C'!I8+'Grade D'!I8+'Grade E'!I8+'Grade F'!I8+'Grade G'!I8),0) | ... GO22: =IFERROR(('Grade A'!GO8*'Grade A'!GO22+'Grade B'!GO8*'Grade B'!GO22+'Grade C'!GO8*'Grade C'!GO22+'Grade D'!GO8*'Grade D'!GO22+'Grade E'!GO8*'Grade E'!GO22+'Grade F'!GO8*'Grade F'!GO22+'Grade G'!GO8*'Grade G'!GO22)/('Grade A'!GO8+'Grade B'!GO8+'Grade C'!GO8+'Grade D'!GO8+'Grade E'!GO8+'Grade F'!GO8+'Grade G'!GO8),0)
A23: 180+ FR | B23: =IFERROR(('Grade A'!B9*'Grade A'!B23+'Grade B'!B9*'Grade B'!B23+'Grade C'!B9*'Grade C'!B23+'Grade D'!B9*'Grade D'!B23+'Grade E'!B9*'Grade E'!B23+'Grade F'!B9*'Grade F'!B23+'Grade G'!B9*'Grade G'!B23)/('Grade A'!B9+'Grade B'!B9+'Grade C'!B9+'Grade D'!B9+'Grade E'!B9+'Grade F'!B9+'Grade G'!B9),0) | C23: =IFERROR(('Grade A'!C9*'Grade A'!C23+'Grade B'!C9*'Grade B'!C23+'Grade C'!C9*'Grade C'!C23+'Grade D'!C9*'Grade D'!C23+'Grade E'!C9*'Grade E'!C23+'Grade F'!C9*'Grade F'!C23+'Grade G'!C9*'Grade G'!C23)/('Grade A'!C9+'Grade B'!C9+'Grade C'!C9+'Grade D'!C9+'Grade E'!C9+'Grade F'!C9+'Grade G'!C9),0) | D23: =IFERROR(('Grade A'!D9*'Grade A'!D23+'Grade B'!D9*'Grade B'!D23+'Grade C'!D9*'Grade C'!D23+'Grade D'!D9*'Grade D'!D23+'Grade E'!D9*'Grade E'!D23+'Grade F'!D9*'Grade F'!D23+'Grade G'!D9*'Grade G'!D23)/('Grade A'!D9+'Grade B'!D9+'Grade C'!D9+'Grade D'!D9+'Grade E'!D9+'Grade F'!D9+'Grade G'!D9),0) | E23: =IFERROR(('Grade A'!E9*'Grade A'!E23+'Grade B'!E9*'Grade B'!E23+'Grade C'!E9*'Grade C'!E23+'Grade D'!E9*'Grade D'!E23+'Grade E'!E9*'Grade E'!E23+'Grade F'!E9*'Grade F'!E23+'Grade G'!E9*'Grade G'!E23)/('Grade A'!E9+'Grade B'!E9+'Grade C'!E9+'Grade D'!E9+'Grade E'!E9+'Grade F'!E9+'Grade G'!E9),0) | F23: =IFERROR(('Grade A'!F9*'Grade A'!F23+'Grade B'!F9*'Grade B'!F23+'Grade C'!F9*'Grade C'!F23+'Grade D'!F9*'Grade D'!F23+'Grade E'!F9*'Grade E'!F23+'Grade F'!F9*'Grade F'!F23+'Grade G'!F9*'Grade G'!F23)/('Grade A'!F9+'Grade B'!F9+'Grade C'!F9+'Grade D'!F9+'Grade E'!F9+'Grade F'!F9+'Grade G'!F9),0) | G23: =IFERROR(('Grade A'!G9*'Grade A'!G23+'Grade B'!G9*'Grade B'!G23+'Grade C'!G9*'Grade C'!G23+'Grade D'!G9*'Grade D'!G23+'Grade E'!G9*'Grade E'!G23+'Grade F'!G9*'Grade F'!G23+'Grade G'!G9*'Grade G'!G23)/('Grade A'!G9+'Grade B'!G9+'Grade C'!G9+'Grade D'!G9+'Grade E'!G9+'Grade F'!G9+'Grade G'!G9),0) | H23: =IFERROR(('Grade A'!H9*'Grade A'!H23+'Grade B'!H9*'Grade B'!H23+'Grade C'!H9*'Grade C'!H23+'Grade D'!H9*'Grade D'!H23+'Grade E'!H9*'Grade E'!H23+'Grade F'!H9*'Grade F'!H23+'Grade G'!H9*'Grade G'!H23)/('Grade A'!H9+'Grade B'!H9+'Grade C'!H9+'Grade D'!H9+'Grade E'!H9+'Grade F'!H9+'Grade G'!H9),0) | I23: =IFERROR(('Grade A'!I9*'Grade A'!I23+'Grade B'!I9*'Grade B'!I23+'Grade C'!I9*'Grade C'!I23+'Grade D'!I9*'Grade D'!I23+'Grade E'!I9*'Grade E'!I23+'Grade F'!I9*'Grade F'!I23+'Grade G'!I9*'Grade G'!I23)/('Grade A'!I9+'Grade B'!I9+'Grade C'!I9+'Grade D'!I9+'Grade E'!I9+'Grade F'!I9+'Grade G'!I9),0) | ... GO23: =IFERROR(('Grade A'!GO9*'Grade A'!GO23+'Grade B'!GO9*'Grade B'!GO23+'Grade C'!GO9*'Grade C'!GO23+'Grade D'!GO9*'Grade D'!GO23+'Grade E'!GO9*'Grade E'!GO23+'Grade F'!GO9*'Grade F'!GO23+'Grade G'!GO9*'Grade G'!GO23)/('Grade A'!GO9+'Grade B'!GO9+'Grade C'!GO9+'Grade D'!GO9+'Grade E'!GO9+'Grade F'!GO9+'Grade G'!GO9),0)
A24: GCO FR | B24: =IFERROR(('Grade A'!B10*'Grade A'!B24+'Grade B'!B10*'Grade B'!B24+'Grade C'!B10*'Grade C'!B24+'Grade D'!B10*'Grade D'!B24+'Grade E'!B10*'Grade E'!B24+'Grade F'!B10*'Grade F'!B24+'Grade G'!B10*'Grade G'!B24)/('Grade A'!B10+'Grade B'!B10+'Grade C'!B10+'Grade D'!B10+'Grade E'!B10+'Grade F'!B10+'Grade G'!B10),0) | C24: =IFERROR(('Grade A'!C10*'Grade A'!C24+'Grade B'!C10*'Grade B'!C24+'Grade C'!C10*'Grade C'!C24+'Grade D'!C10*'Grade D'!C24+'Grade E'!C10*'Grade E'!C24+'Grade F'!C10*'Grade F'!C24+'Grade G'!C10*'Grade G'!C24)/('Grade A'!C10+'Grade B'!C10+'Grade C'!C10+'Grade D'!C10+'Grade E'!C10+'Grade F'!C10+'Grade G'!C10),0) | D24: =IFERROR(('Grade A'!D10*'Grade A'!D24+'Grade B'!D10*'Grade B'!D24+'Grade C'!D10*'Grade C'!D24+'Grade D'!D10*'Grade D'!D24+'Grade E'!D10*'Grade E'!D24+'Grade F'!D10*'Grade F'!D24+'Grade G'!D10*'Grade G'!D24)/('Grade A'!D10+'Grade B'!D10+'Grade C'!D10+'Grade D'!D10+'Grade E'!D10+'Grade F'!D10+'Grade G'!D10),0) | E24: =IFERROR(('Grade A'!E10*'Grade A'!E24+'Grade B'!E10*'Grade B'!E24+'Grade C'!E10*'Grade C'!E24+'Grade D'!E10*'Grade D'!E24+'Grade E'!E10*'Grade E'!E24+'Grade F'!E10*'Grade F'!E24+'Grade G'!E10*'Grade G'!E24)/('Grade A'!E10+'Grade B'!E10+'Grade C'!E10+'Grade D'!E10+'Grade E'!E10+'Grade F'!E10+'Grade G'!E10),0) | F24: =IFERROR(('Grade A'!F10*'Grade A'!F24+'Grade B'!F10*'Grade B'!F24+'Grade C'!F10*'Grade C'!F24+'Grade D'!F10*'Grade D'!F24+'Grade E'!F10*'Grade E'!F24+'Grade F'!F10*'Grade F'!F24+'Grade G'!F10*'Grade G'!F24)/('Grade A'!F10+'Grade B'!F10+'Grade C'!F10+'Grade D'!F10+'Grade E'!F10+'Grade F'!F10+'Grade G'!F10),0) | G24: =IFERROR(('Grade A'!G10*'Grade A'!G24+'Grade B'!G10*'Grade B'!G24+'Grade C'!G10*'Grade C'!G24+'Grade D'!G10*'Grade D'!G24+'Grade E'!G10*'Grade E'!G24+'Grade F'!G10*'Grade F'!G24+'Grade G'!G10*'Grade G'!G24)/('Grade A'!G10+'Grade B'!G10+'Grade C'!G10+'Grade D'!G10+'Grade E'!G10+'Grade F'!G10+'Grade G'!G10),0) | H24: =IFERROR(('Grade A'!H10*'Grade A'!H24+'Grade B'!H10*'Grade B'!H24+'Grade C'!H10*'Grade C'!H24+'Grade D'!H10*'Grade D'!H24+'Grade E'!H10*'Grade E'!H24+'Grade F'!H10*'Grade F'!H24+'Grade G'!H10*'Grade G'!H24)/('Grade A'!H10+'Grade B'!H10+'Grade C'!H10+'Grade D'!H10+'Grade E'!H10+'Grade F'!H10+'Grade G'!H10),0) | I24: =IFERROR(('Grade A'!I10*'Grade A'!I24+'Grade B'!I10*'Grade B'!I24+'Grade C'!I10*'Grade C'!I24+'Grade D'!I10*'Grade D'!I24+'Grade E'!I10*'Grade E'!I24+'Grade F'!I10*'Grade F'!I24+'Grade G'!I10*'Grade G'!I24)/('Grade A'!I10+'Grade B'!I10+'Grade C'!I10+'Grade D'!I10+'Grade E'!I10+'Grade F'!I10+'Grade G'!I10),0) | ... GO24: =IFERROR(('Grade A'!GO10*'Grade A'!GO24+'Grade B'!GO10*'Grade B'!GO24+'Grade C'!GO10*'Grade C'!GO24+'Grade D'!GO10*'Grade D'!GO24+'Grade E'!GO10*'Grade E'!GO24+'Grade F'!GO10*'Grade F'!GO24+'Grade G'!GO10*'Grade G'!GO24)/('Grade A'!GO10+'Grade B'!GO10+'Grade C'!GO10+'Grade D'!GO10+'Grade E'!GO10+'Grade F'!GO10+'Grade G'!GO10),0)
A26: Flow-Through Rate
A27: Metric | B27: 2007-06 | C27: 2007-07 | D27: 2007-08 | E27: 2007-09 | F27: 2007-10 | G27: 2007-11 | H27: 2007-12 | I27: 2008-01 | J27: 2008-02 | K27: 2008-03 | L27: 2008-04 | M27: 2008-05 | N27: 2008-06 | O27: 2008-07 | P27: 2008-08 | Q27: 2008-09 | R27: 2008-10 | S27: 2008-11 | T27: 2008-12 | U27: 2009-01 | V27: 2009-02 | W27: 2009-03 | X27: 2009-04 | Y27: 2009-05 | Z27: 2009-06 | AA27: 2009-07 | AB27: 2009-08 | AC27: 2009-09 | AD27: 2009-10 | AE27: 2009-11 | AF27: 2009-12 | AG27: 2010-01 | AH27: 2010-02 | AI27: 2010-03 | AJ27: 2010-04 | AK27: 2010-05 | AL27: 2010-06 | AM27: 2010-07 | AN27: 2010-08 | AO27: 2010-09 | AP27: 2010-10 | AQ27: 2010-11 | AR27: 2010-12 | AS27: 2011-01 | AT27: 2011-02 | AU27: 2011-03 | AV27: 2011-04 | AW27: 2011-05 | AX27: 2011-06 | AY27: 2011-07 | AZ27: 2011-08 | BA27: 2011-09 | BB27: 2011-10 | BC27: 2011-11 | BD27: 2011-12 | BE27: 2012-01 | BF27: 2012-02 | BG27: 2012-03 | BH27: 2012-04 | BI27: 2012-05 | BJ27: 2012-06 | BK27: 2012-07 | BL27: 2012-08 | BM27: 2012-09 | BN27: 2012-10 | BO27: 2012-11 | BP27: 2012-12 | BQ27: 2013-01 | BR27: 2013-02 | BS27: 2013-03 | BT27: 2013-04 | BU27: 2013-05 | BV27: 2013-06 | BW27: 2013-07 | BX27: 2013-08 | BY27: 2013-09 | BZ27: 2013-10 | CA27: 2013-11 | CB27: 2013-12 | CC27: 2014-01 | CD27: 2014-02 | CE27: 2014-03 | CF27: 2014-04 | CG27: 2014-05 | CH27: 2014-06 | CI27: 2014-07 | CJ27: 2014-08 | CK27: 2014-09 | CL27: 2014-10 | CM27: 2014-11 | CN27: 2014-12 | CO27: 2015-01 | CP27: 2015-02 | CQ27: 2015-03 | CR27: 2015-04 | CS27: 2015-05 | CT27: 2015-06 | CU27: 2015-07 | CV27: 2015-08 | CW27: 2015-09 | CX27: 2015-10 | CY27: 2015-11 | CZ27: 2015-12 | DA27: 2016-01 | DB27: 2016-02 | DC27: 2016-03 | DD27: 2016-04 | DE27: 2016-05 | DF27: 2016-06 | DG27: 2016-07 | DH27: 2016-08 | DI27: 2016-09 | DJ27: 2016-10 | DK27: 2016-11 | DL27: 2016-12 | DM27: 2017-01 | DN27: 2017-02 | DO27: 2017-03 | DP27: 2017-04 | DQ27: 2017-05 | DR27: 2017-06 | DS27: 2017-07 | DT27: 2017-08 | DU27: 2017-09 | DV27: 2017-10 | DW27: 2017-11 | DX27: 2017-12 | DY27: 2018-01 | DZ27: 2018-02 | EA27: 2018-03 | EB27: 2018-04 | EC27: 2018-05 | ED27: 2018-06 | EE27: 2018-07 | EF27: 2018-08 | EG27: 2018-09 | EH27: 2018-10 | EI27: 2018-11 | EJ27: 2018-12 | EK27: 2019-01 | EL27: 2019-02 | EM27: 2019-03 | EN27: 2019-04 | EO27: 2019-05 | EP27: 2019-06 | EQ27: 2019-07 | ER27: 2019-08 | ES27: 2019-09 | ET27: 2019-10 | EU27: 2019-11 | EV27: 2019-12 | EW27: 2020-01 | EX27: 2020-02 | EY27: 2020-03 | EZ27: 2020-04 | FA27: 2020-05 | FB27: 2020-06 | FC27: 2020-07 | FD27: 2020-08 | FE27: 2020-09 | FF27: 2020-10 | FG27: 2020-11 | FH27: 2020-12 | FI27: 2021-01 | FJ27: 2021-02 | FK27: 2021-03 | FL27: 2021-04 | FM27: 2021-05 | FN27: 2021-06 | FO27: 2021-07 | FP27: 2021-08 | FQ27: 2021-09 | FR27: 2021-10 | FS27: 2021-11 | FT27: 2021-12 | FU27: 2022-01 | FV27: 2022-02 | FW27: 2022-03 | FX27: 2022-04 | FY27: 2022-05 | FZ27: 2022-06 | GA27: 2022-07 | GB27: 2022-08 | GC27: 2022-09 | GD27: 2022-10 | GE27: 2022-11 | GF27: 2022-12 | GG27: 2023-01 | GH27: 2023-02 | GI27: 2023-03 | GJ27: 2023-04 | GK27: 2023-05 | GL27: 2023-06 | GM27: 2023-07 | GN27: 2023-08 | GO27: 2023-09
A28: FTR (Calculated) | B28: =PRODUCT(B18:B24) | C28: =PRODUCT(C18:C24) | D28: =PRODUCT(D18:D24) | E28: =PRODUCT(E18:E24) | F28: =PRODUCT(F18:F24) | G28: =PRODUCT(G18:G24) | H28: =PRODUCT(H18:H24) | I28: =PRODUCT(I18:I24) | ... GO28: =PRODUCT(GO18:GO24)

Sheet Data
A1: Grade A - Balances | B1: 39234 | C1: 39264 | D1: 39295 | E1: 39326 | F1: 39356 | G1: 39387 | H1: 39417 | I1: 39448 | J1: 39479 | K1: 39508 | L1: 39539 | M1: 39569 | N1: 39600 | O1: 39630 | P1: 39661 | Q1: 39692 | R1: 39722 | S1: 39753 | T1: 39783 | U1: 39814 | V1: 39845 | W1: 39873 | X1: 39904 | Y1: 39934 | Z1: 39965 | AA1: 39995 | AB1: 40026 | AC1: 40057 | AD1: 40087 | AE1: 40118 | AF1: 40148 | AG1: 40179 | AH1: 40210 | AI1: 40238 | AJ1: 40269 | AK1: 40299 | AL1: 40330 | AM1: 40360 | AN1: 40391 | AO1: 40422 | AP1: 40452 | AQ1: 40483 | AR1: 40513 | AS1: 40544 | AT1: 40575 | AU1: 40603 | AV1: 40634 | AW1: 40664 | AX1: 40695 | AY1: 40725 | AZ1: 40756 | BA1: 40787 | BB1: 40817 | BC1: 40848 | BD1: 40878 | BE1: 40909 | BF1: 40940 | BG1: 40969 | BH1: 41000 | BI1: 41030 | BJ1: 41061 | BK1: 41091 | BL1: 41122 | BM1: 41153 | BN1: 41183 | BO1: 41214 | BP1: 41244 | BQ1: 41275 | BR1: 41306 | BS1: 41334 | BT1: 41365 | BU1: 41395 | BV1: 41426 | BW1: 41456 | BX1: 41487 | BY1: 41518 | BZ1: 41548 | CA1: 41579 | CB1: 41609 | CC1: 41640 | CD1: 41671 | CE1: 41699 | CF1: 41730 | CG1: 41760 | CH1: 41791 | CI1: 41821 | CJ1: 41852 | CK1: 41883 | CL1: 41913 | CM1: 41944 | CN1: 41974 | CO1: 42005 | CP1: 42036 | CQ1: 42064 | CR1: 42095 | CS1: 42125 | CT1: 42156 | CU1: 42186 | CV1: 42217 | CW1: 42248 | CX1: 42278 | CY1: 42309 | CZ1: 42339 | DA1: 42370 | DB1: 42401 | DC1: 42430 | DD1: 42461 | DE1: 42491 | DF1: 42522 | DG1: 42552 | DH1: 42583 | DI1: 42614 | DJ1: 42644 | DK1: 42675 | DL1: 42705 | DM1: 42736 | DN1: 42767 | DO1: 42795 | DP1: 42826 | DQ1: 42856 | DR1: 42887 | DS1: 42917 | DT1: 42948 | DU1: 42979 | DV1: 43009 | DW1: 43040 | DX1: 43070 | DY1: 43101 | DZ1: 43132 | EA1: 43160 | EB1: 43191 | EC1: 43221 | ED1: 43252 | EE1: 43282 | EF1: 43313 | EG1: 43344 | EH1: 43374 | EI1: 43405 | EJ1: 43435 | EK1: 43466 | EL1: 43497 | EM1: 43525 | EN1: 43556 | EO1: 43586 | EP1: 43617 | EQ1: 43647 | ER1: 43678 | ES1: 43709 | ET1: 43739 | EU1: 43770 | EV1: 43800 | EW1: 43831 | EX1: 43862 | EY1: 43891 | EZ1: 43922 | FA1: 43952 | FB1: 43983 | FC1: 44013 | FD1: 44044 | FE1: 44075 | FF1: 44105 | FG1: 44136 | FH1: 44166 | FI1: 44197 | FJ1: 44228 | FK1: 44256 | FL1: 44287 | FM1: 44317 | FN1: 44348 | FO1: 44378 | FP1: 44409 | FQ1: 44440 | FR1: 44470 | FS1: 44501 | FT1: 44531 | FU1: 44562 | FV1: 44593 | FW1: 44621 | FX1: 44652 | FY1: 44682 | FZ1: 44713 | GA1: 44743 | GB1: 44774 | GC1: 44805 | GD1: 44835 | GE1: 44866 | GF1: 44896 | GG1: 44927 | GH1: 44958 | GI1: 44986 | GJ1: 45017 | GK1: 45047 | GL1: 45078 | GM1: 45108 | GN1: 45139 | GO1: 45170
A2: Current | B2: 0 | C2: 64050 | D2: 107463.59 | E2: 136251.67 | F2: 180443.53 | G2: 242685.26 | H2: 294141.51 | I2: 556800.25 | J2: 723486.9 | K2: 904548.8 | L2: 993815.62 | M2: 1022577.4 | N2: 1041386.8 | O2: 1116578.4 | P2: 1120338.1 | Q2: 1119545.3 | R2: 1204754 | S2: 1338544.4 | T2: 1640440.6 | U2: 2012185.1 | V2: 2358169.9 | W2: 2787859.3 | X2: 3302487.9 | Y2: 3668219.9 | Z2: 4209369.1 | AA2: 4734973.4 | AB2: 5355905.1 | AC2: 6081062.6 | AD2: 6762929.7 | AE2: 7510857.4 | AF2: 8286220.2 | AG2: 8990622.8 | AH2: 9640419 | AI2: 10414808 | AJ2: 11099231 | AK2: 12268454 | AL2: 13573264 | AM2: 15100581 | AN2: 15940209 | AO2: 17195064 | AP2: 19221405 | AQ2: 21128473 | AR2: 23983917 | AS2: 26460328 | AT2: 28119775 | AU2: 29757682 | AV2: 31100269 | AW2: 32907838 | AX2: 35091986 | AY2: 37341636 | AZ2: 40645227 | BA2: 45034723 | BB2: 49943237 | BC2: 53903756 | BD2: 56455135 | BE2: 61525583 | BF2: 67664395 | BG2: 74213298 | BH2: 79604152 | BI2: 85496015 | BJ2: 89336288 | BK2: 94081818 | BL2: 1.0155473e+08 | BM2: 1.0854135e+08 | BN2: 1.1502232e+08 | BO2: 1.1997149e+08 | BP2: 1.3069934e+08 | BQ2: 1.4057777e+08 | BR2: 1.5257855e+08 | BS2: 1.6818718e+08 | BT2: 1.8210189e+08 | BU2: 1.906347e+08 | BV2: 1.9954699e+08 | BW2: 2.1080066e+08 | BX2: 2.2120378e+08 | BY2: 2.3071586e+08 | BZ2: 2.4507086e+08 | CA2: 2.7190595e+08 | CB2: 2.9627143e+08 | CC2: 3.1883856e+08 | CD2: 3.3788203e+08 | CE2: 3.5384975e+08 | CF2: 3.7631861e+08 | CG2: 3.9736825e+08 | CH2: 4.1125115e+08 | CI2: 4.4463214e+08 | CJ2: 4.673362e+08 | CK2: 4.7563955e+08 | CL2: 5.5224526e+08 | CM2: 5.8234626e+08 | CN2: 5.8534217e+08 | CO2: 6.4509767e+08 | CP2: 6.7764975e+08 | CQ2: 7.0665755e+08 | CR2: 7.5845282e+08 | CS2: 8.0481154e+08 | CT2: 8.3706647e+08 | CU2: 9.0710169e+08 | CV2: 9.4845208e+08 | CW2: 9.7394104e+08 | CX2: 1.0532717e+09 | CY2: 1.0955226e+09 | CZ2: 1.1519079e+09 | DA2: 1.1888318e+09 | DB2: 1.2329593e+09 | DC2: 1.3342901e+09 | DD2: 1.3392334e+09 | DE2: 1.3223776e+09 | DF2: 1.3099514e+09 | DG2: 1.2701025e+09 | DH2: 1.2280948e+09 | DI2: 1.179207e+09 | DJ2: 1.1371796e+09 | DK2: 1.0936934e+09 | DL2: 1.0524175e+09 | DM2: 1.0107764e+09 | DN2: 9.6546304e+08 | DO2: 9.3200228e+08 | DP2: 8.8370774e+08 | DQ2: 8.4941515e+08 | DR2: 8.1346356e+08 | DS2: 7.7290412e+08 | DT2: 7.3667678e+08 | DU2: 6.9503841e+08 | DV2: 6.6153919e+08 | DW2: 6.3166732e+08 | DX2: 5.9684289e+08 | DY2: 5.6542324e+08 | DZ2: 5.2373769e+08 | EA2: 4.8744921e+08 | EB2: 4.438859e+08 | EC2: 4.0860016e+08 | ED2: 3.7038543e+08 | EE2: 3.3072807e+08 | EF2: 2.8907246e+08 | EG2: 2.4514382e+08 | EH2: 2.0838549e+08 | EI2: 1.6629112e+08 | EJ2: 1.2932303e+08 | EK2: 93279017 | EL2: 55278589 | EM2: 16800786 | EN2: 1002300.6 | EO2: 958768.58 | EP2: 915973.25 | EQ2: 874303.36 | ER2: 832589.37 | ES2: 791399.32 | ET2: 750334.87 | EU2: 709026.23 | EV2: 667935.03 | EW2: 627416.35 | EX2: 587596.6 | EY2: 547540.61 | EZ2: 508811.15 | FA2: 470965.93 | FB2: 434194.05 | FC2: 399073.82 | FD2: 363963.35 | FE2: 330188.18 | FF2: 297296 | FG2: 265337.21 | FH2: 233594.55 | FI2: 205140.34 | FJ2: 181520.38 | FK2: 158509.85 | FL2: 138530.24 | FM2: 122177.61 | FN2: 107333.16 | FO2: 96277.86 | FP2: 85497.25 | FQ2: 76704.383 | FR2: 69791.769 | FS2: 65628.959 | FT2: 61756.953 | FU2: 58105.844 | FV2: 54431.756 | FW2: 50734.543 | FX2: 47014.059 | FY2: 43270.158 | FZ2: 39502.692 | GA2: 35711.512 | GB2: 31896.47 | GC2: 28057.414 | GD2: 24194.194 | GE2: 20306.657 | GF2: 16876.886 | GG2: 13425.694 | GH2: 9952.9459 | GI2: 7676.4796 | GJ2: 5816.8269 | GK2: 4743.8352 | GL2: 3663.8334 | GM2: 2576.7755 | GN2: 1482.6155 | GO2: 381.30704
A3: 30+ | B3: 0 | C3: 0 | D3: 0 | E3: 0 | F3: 0 | G3: 0 | H3: 0 | I3: 0 | J3: 0 | K3: 0 | L3: 0 | M3: 0 | N3: 0 | O3: 0 | P3: 0 | Q3: 0 | R3: 0 | S3: 0 | T3: 0 | U3: 0 | V3: 0 | W3: 0 | X3: 0 | Y3: 13804.916 | Z3: 1808.831 | AA3: 1002.2631 | AB3: 0 | AC3: 0 | AD3: 14601.749 | AE3: 8842.7661 | AF3: 0 | AG3: 29117.124 | AH3: 8938.1764 | AI3: 7441.3982 | AJ3: 64846.559 | AK3: 23069.616 | AL3: 11774.678 | AM3: 6181.1603 | AN3: 22491.218 | AO3: 23590.307 | AP3: 10994.576 | AQ3: 10385.209 | AR3: 18905.391 | AS3: 27903.791 | AT3: 9966.5042 | AU3: 39923.728 | AV3: 28059.785 | AW3: 41678.161 | AX3: 25243.405 | AY3: 23089.206 | AZ3: 53863.352 | BA3: 89706.248 | BB3: 47506.527 | BC3: 58819.64 | BD3: 59797.5 | BE3: 41026.854 | BF3: 41196.372 | BG3: 70181.664 | BH3: 76380.693 | BI3: 150779.23 | BJ3: 139755.23 | BK3: 118069.77 | BL3: 176016.47 | BM3: 220941.73 | BN3: 164538.09 | BO3: 265220.96 | BP3: 210175.15 | BQ3: 219052.92 | BR3: 282951.04 | BS3: 271498.82 | BT3: 297649.87 | BU3: 274526.59 | BV3: 204310.05 | BW3: 275021.3 | BX3: 287377.7 | BY3: 381179.56 | BZ3: 279582.73 | CA3: 332866.49 | CB3: 214684.71 | CC3: 326265.69 | CD3: 363695.39 | CE3: 229307.43 | CF3: 319428.8 | CG3: 379673.76 | CH3: 342129.82 | CI3: 512511.41 | CJ3: 459858.84 | CK3: 501483.62 | CL3: 475840.55 | CM3: 587533.16 | CN3: 435586.94 | CO3: 736531.9 | CP3: 642468.87 | CQ3: 737266.91 | CR3: 811283.43 | CS3: 917467.38 | CT3: 787158.12 | CU3: 832297.45 | CV3: 1220484.1 | CW3: 1117420.9 | CX3: 1116056.3 | CY3: 1264515.4 | CZ3: 903031.79 | DA3: 1377682.1 | DB3: 1438557.5 | DC3: 1119483.8 | DD3: 1742795.5 | DE3: 1651720.7 | DF3: 1556205.9 | DG3: 2364392.1 | DH3: 1869370.7 | DI3: 2280237.8 | DJ3: 2648443.1 | DK3: 2426723.3 | DL3: 2182648.8 | DM3: 2262457.7 | DN3: 2668882.8 | DO3: 2037112 | DP3: 2380550.8 | DQ3: 2574914.1 | DR3: 2291906 | DS3: 2321171.9 | DT3: 2173382.5 | DU3: 2535503.9 | DV3: 1993946.7 | DW3: 2232229.6 | DX3: 2211802.1 | DY3: 2280424.6 | DZ3: 2301614.6 | EA3: 1908371.5 | EB3: 2632577.8 | EC3: 2444770.7 | ED3: 2565294.3 | EE3: 2756089.1 | EF3: 3059621.7 | EG3: 3459336.7 | EH3: 2667814.5 | EI3: 3800497.3 | EJ3: 1264926.6 | EK3: 584442.93 | EL3: 591137.38 | EM3: 227919.94 | EN3: 166237.67 | EO3: 0 | EP3: 0 | EQ3: 0 | ER3: 0 | ES3: 0 | ET3: 0 | EU3: 0 | EV3: 0 | EW3: 0 | EX3: 0 | EY3: 0 | EZ3: 0 | FA3: 0 | FB3: 0 | FC3: 0 | FD3: 0 | FE3: 0 | FF3: 0 | FG3: 0 | FH3: 0 | FI3: 0 | FJ3: 0 | FK3: 0 | FL3: 0 | FM3: 0 | FN3: 0 | FO3: 0 | FP3: 0 | FQ3: 0 | FR3: 0 | FS3: 0 | FT3: 0 | FU3: 0 | FV3: 0 | FW3: 0 | FX3: 0 | FY3: 0 | FZ3: 0 | GA3: 0 | GB3: 0 | GC3: 0 | GD3: 0 | GE3: 0 | GF3: 0 | GG3: 0 | GH3: 0 | GI3: 0 | GJ3: 0 | GK3: 0 | GL3: 0 | GM3: 0 | GN3: 0 | GO3: 0
A4: 60+ | B4: 0 | C4: 0 | D4: 0 | E4: 0 | F4: 0 | G4: 0 | H4: 0 | I4: 0 | J4: 0 | K4: 0 | L4: 0 | M4: 0 | N4: 0 | O4: 0 | P4: 0 | Q4: 0 | R4: 0 | S4: 0 | T4: 0 | U4: 0 | V4: 0 | W4: 0 | X4: 0 | Y4: 0 | Z4: 13320.668 | AA4: 1719.0442 | AB4: 946.29376 | AC4: 0 | AD4: 0 | AE4: 14091.354 | AF4: 8528.4138 | AG4: 0 | AH4: 28135.22 | AI4: 8621.1133 | AJ4: 7091.7613 | AK4: 61754.262 | AL4: 22182.84 | AM4: 11266.978 | AN4: 5949.2863 | AO4: 21609.349 | AP4: 22791.906 | AQ4: 10669.782 | AR4: 9783.522 | AS4: 18090.783 | AT4: 26659.445 | AU4: 9450.4363 | AV4: 38124.096 | AW4: 26462.525 | AX4: 39732.309 | AY4: 24590.444 | AZ4: 22304.07 | BA4: 52143.829 | BB4: 85962.156 | BC4: 45246.082 | BD4: 55795.934 | BE4: 57909.284 | BF4: 39352.122 | BG4: 39652.389 | BH4: 67082.317 | BI4: 72868.83 | BJ4: 145385.65 | BK4: 134160.06 | BL4: 113630.48 | BM4: 169698.47 | BN4: 213393.02 | BO4: 158230.05 | BP4: 254781.45 | BQ4: 202848.71 | BR4: 210673.49 | BS4: 271796.45 | BT4: 261048.07 | BU4: 286048.07 | BV4: 263626.63 | BW4: 195705.26 | BX4: 263073.82 | BY4: 275187.57 | BZ4: 365922.43 | CA4: 265912.02 | CB4: 317977.34 | CC4: 203478.54 | CD4: 310495.44 | CE4: 347998.88 | CF4: 218816.06 | CG4: 304899.25 | CH4: 363142.75 | CI4: 328243.39 | CJ4: 490848.35 | CK4: 434662.63 | CL4: 480568 | CM4: 454241.32 | CN4: 557776.66 | CO4: 416020.36 | CP4: 703996.44 | CQ4: 613382.02 | CR4: 701853.06 | CS4: 774897.95 | CT4: 877411.86 | CU4: 750910.41 | CV4: 792805.12 | CW4: 1165715.5 | CX4: 1066458.9 | CY4: 1068536.7 | CZ4: 1207697.5 | DA4: 860308.78 | DB4: 1316391.8 | DC4: 1374179.4 | DD4: 1067835.8 | DE4: 1662941.4 | DF4: 1576929.4 | DG4: 1485074.6 | DH4: 2259389.2 | DI4: 1774047.8 | DJ4: 2172785.5 | DK4: 2518742.3 | DL4: 2308573.6 | DM4: 2084501.1 | DN4: 2153494.2 | DO4: 2538084.6 | DP4: 1932708.3 | DQ4: 2254014.4 | DR4: 2442607.1 | DS4: 2173598.1 | DT4: 2198228.3 | DU4: 2054994.4 | DV4: 2394251.1 | DW4: 1887182.5 | DX4: 2103125.7 | DY4: 2090602.4 | DZ4: 2163175.6 | EA4: 2175763.5 | EB4: 1807662.8 | EC4: 2492778.8 | ED4: 2320376.8 | EE4: 2448258.4 | EF4: 2619435.6 | EG4: 2912928 | EH4: 3298300.4 | EI4: 2536404.9 | EJ4: 3633958.5 | EK4: 1203672.5 | EL4: 547589.52 | EM4: 559097.28 | EN4: 214144.51 | EO4: 153631.36 | EP4: 0 | EQ4: 0 | ER4: 0 | ES4: 0 | ET4: 0 | EU4: 0 | EV4: 0 | EW4: 0 | EX4: 0 | EY4: 0 | EZ4: 0 | FA4: 0 | FB4: 0 | FC4: 0 | FD4: 0 | FE4: 0 | FF4: 0 | FG4: 0 | FH4: 0 | FI4: 0 | FJ4: 0 | FK4: 0 | FL4: 0 | FM4: 0 | FN4: 0 | FO4: 0 | FP4: 0 | FQ4: 0 | FR4: 0 | FS4: 0 | FT4: 0 | FU4: 0 | FV4: 0 | FW4: 0 | FX4: 0 | FY4: 0 | FZ4: 0 | GA4: 0 | GB4: 0 | GC4: 0 | GD4: 0 | GE4: 0 | GF4: 0 | GG4: 0 | GH4: 0 | GI4: 0 | GJ4: 0 | GK4: 0 | GL4: 0 | GM4: 0 | GN4: 0 | GO4: 0
A5: 90+ | B5: 0 | C5: 0 | D5: 0 | E5: 0 | F5: 0 | G5: 0 | H5: 0 | I5: 0 | J5: 0 | K5: 0 | L5: 0 | M5: 0 | N5: 0 | O5: 0 | P5: 0 | Q5: 0 | R5: 0 | S5: 0 | T5: 0 | U5: 0 | V5: 0 | W5: 0 | X5: 0 | Y5: 0 | Z5: 0 | AA5: 12832.826 | AB5: 1628.6776 | AC5: 889.96291 | AD5: 0 | AE5: 0 | AF5: 13577.208 | AG5: 8211.5759 | AH5: 0 | AI5: 27145.832 | AJ5: 8302.021 | AK5: 6739.5631 | AL5: 58639.108 | AM5: 21289.381 | AN5: 10755.634 | AO5: 5715.6221 | AP5: 20721.228 | AQ5: 21987.898 | AR5: 10342.498 | AS5: 9177.5388 | AT5: 17270.673 | AU5: 25405.851 | AV5: 8930.5435 | AW5: 36312.779 | AX5: 25003.469 | AY5: 37773.152 | AZ5: 23933.622 | BA5: 21514.225 | BB5: 50413.715 | BC5: 82194.504 | BD5: 42970.707 | BE5: 52752.443 | BF5: 56009.329 | BG5: 37699.617 | BH5: 38099.153 | BI5: 63962.445 | BJ5: 69555.174 | BK5: 139959.38 | BL5: 128722.96 | BM5: 109163.55 | BN5: 163339.59 | BO5: 205797.86 | BP5: 151880.83 | BQ5: 244385.04 | BR5: 195473.39 | BS5: 202239.16 | BT5: 260617.62 | BU5: 250531.27 | BV5: 274369.85 | BW5: 252657.66 | BX5: 187045.02 | BY5: 251046.85 | BZ5: 262998.2 | CA5: 350563.25 | CB5: 252342.69 | CC5: 302990.01 | CD5: 192505.97 | CE5: 294620 | CF5: 332656.97 | CG5: 208256.56 | CH5: 291057.9 | CI5: 346505.17 | CJ5: 314264.9 | CK5: 469043.26 | CL5: 409530.85 | CM5: 459511.3 | CN5: 432496.39 | CO5: 527821.75 | CP5: 396624.3 | CQ5: 672919.73 | CR5: 584576.59 | CS5: 666210.2 | CT5: 738272.45 | CU5: 837090.7 | CV5: 714881 | CW5: 753644.61 | CX5: 1110955.5 | CY5: 1015164.3 | CZ5: 1020710.2 | DA5: 1150513.2 | DB5: 818201.01 | DC5: 1254721.1 | DD5: 1310046.5 | DE5: 1015988.5 | DF5: 1582579.9 | DG5: 1501672.5 | DH5: 1413792 | DI5: 2154278.2 | DJ5: 1678295.3 | DK5: 2065090.4 | DL5: 2391925 | DM5: 2190657.4 | DN5: 1986185.2 | DO5: 2044495.4 | DP5: 2406998.5 | DQ5: 1829547.9 | DR5: 2127240.1 | DS5: 2310544.4 | DT5: 2057074.8 | DU5: 2074547.2 | DV5: 1936288.3 | DW5: 2256433.1 | DX5: 1781004.7 | DY5: 1974306.1 | DZ5: 1969998.7 | EA5: 2046425 | EB5: 2051553 | EC5: 1708463.7 | ED5: 2355119.8 | EE5: 2198064.5 | EF5: 2333681.3 | EG5: 2485973.8 | EH5: 2768404.2 | EI5: 3141812.6 | EJ5: 2407723.4 | EK5: 3468453.7 | EL5: 1142914.6 | EM5: 512701.48 | EN5: 529351.1 | EO5: 200412.37 | EP5: 142113.93 | EQ5: 0 | ER5: 0 | ES5: 0 | ET5: 0 | EU5: 0 | EV5: 0 | EW5: 0 | EX5: 0 | EY5: 0 | EZ5: 0 | FA5: 0 | FB5: 0 | FC5: 0 | FD5: 0 | FE5: 0 | FF5: 0 | FG5: 0 | FH5: 0 | FI5: 0 | FJ5: 0 | FK5: 0 | FL5: 0 | FM5: 0 | FN5: 0 | FO5: 0 | FP5: 0 | FQ5: 0 | FR5: 0 | FS5: 0 | FT5: 0 | FU5: 0 | FV5: 0 | FW5: 0 | FX5: 0 | FY5: 0 | FZ5: 0 | GA5: 0 | GB5: 0 | GC5: 0 | GD5: 0 | GE5: 0 | GF5: 0 | GG5: 0 | GH5: 0 | GI5: 0 | GJ5: 0 | GK5: 0 | GL5: 0 | GM5: 0 | GN5: 0 | GO5: 0
A6: 120+ | B6: 0 | C6: 0 | D6: 0 | E6: 0 | F6: 0 | G6: 0 | H6: 0 | I6: 0 | J6: 0 | K6: 0 | L6: 0 | M6: 0 | N6: 0 | O6: 0 | P6: 0 | Q6: 0 | R6: 0 | S6: 0 | T6: 0 | U6: 0 | V6: 0 | W6: 0 | X6: 0 | Y6: 0 | Z6: 0 | AA6: 0 | AB6: 12341.364 | AC6: 1537.7274 | AD6: 833.26826 | AE6: 0 | AF6: 0 | AG6: 13059.283 | AH6: 7892.233 | AI6: 0 | AJ6: 26148.904 | AK6: 7980.8865 | AL6: 6384.7848 | AM6: 55500.927 | AN6: 20389.191 | AO6: 10240.617 | AP6: 5480.1539 | AQ6: 19826.81 | AR6: 21178.243 | AS6: 10012.707 | AT6: 8793.0835 | AU6: 16445.025 | AV6: 24142.939 | AW6: 8406.7969 | AX6: 34489.702 | AY6: 23534.02 | AZ6: 35800.597 | BA6: 23272.915 | BB6: 20719.641 | BC6: 48672.942 | BD6: 78403.139 | BE6: 41105.596 | BF6: 49689.036 | BG6: 54097.563 | BH6: 36037.579 | BI6: 36536.609 | BJ6: 60821.911 | BK6: 66221.703 | BL6: 134500.2 | BM6: 123253.53 | BN6: 104668.82 | BO6: 156939.54 | BP6: 198314.81 | BQ6: 145490.14 | BR6: 233921.43 | BS6: 188048.87 | BT6: 193749.56 | BU6: 249367.71 | BV6: 239948.03 | BW6: 262614.68 | BX6: 241619.22 | BY6: 178328.96 | BZ6: 238939.85 | CA6: 250729.09 | CB6: 335101.32 | CC6: 238685.06 | CD6: 288184.46 | CE6: 181459.88 | CF6: 278638.66 | CG6: 317215.44 | CH6: 197779.3 | CI6: 277124.96 | CJ6: 329760.34 | CK6: 300193.74 | CL6: 447095.2 | CM6: 384678.57 | CN6: 438312.55 | CO6: 410604.77 | CP6: 497947.09 | CQ6: 377544.63 | CR6: 641795.17 | CS6: 555578.48 | CT6: 630560.07 | CU6: 701787.04 | CV6: 796502.11 | CW6: 678931.6 | CX6: 714226.8 | CY6: 1056151.2 | CZ6: 963889.18 | DA6: 972574.87 | DB6: 1094361.4 | DC6: 775824.21 | DD6: 1192667.6 | DE6: 1247448.1 | DF6: 963856.14 | DG6: 1502133.9 | DH6: 1426258.9 | DI6: 1342706.8 | DJ6: 2049560.8 | DK6: 1583310.6 | DL6: 1957622.4 | DM6: 2267087 | DN6: 2074347.2 | DO6: 1887280.5 | DP6: 1935586.8 | DQ6: 2276892.7 | DR6: 1725767.9 | DS6: 2000885.4 | DT6: 2179760.8 | DU6: 1941333.3 | DV6: 1952333.3 | DW6: 1819914.6 | DX6: 2121345.7 | DY6: 1674493.5 | DZ6: 1847006.5 | EA6: 1851731.7 | EB6: 1929957.3 | EC6: 1930270.9 | ED6: 1610430.9 | EE6: 2219626 | EF6: 2078949.9 | EG6: 2219692.9 | EH6: 2352567.1 | EI6: 2627674.9 | EJ6: 2987682.9 | EK6: 2281522.3 | EL6: 3305468.7 | EM6: 1085326.8 | EN6: 482716.72 | EO6: 500789.29 | EP6: 186926.91 | EQ6: 132033.66 | ER6: 0 | ES6: 0 | ET6: 0 | EU6: 0 | EV6: 0 | EW6: 0 | EX6: 0 | EY6: 0 | EZ6: 0 | FA6: 0 | FB6: 0 | FC6: 0 | FD6: 0 | FE6: 0 | FF6: 0 | FG6: 0 | FH6: 0 | FI6: 0 | FJ6: 0 | FK6: 0 | FL6: 0 | FM6: 0 | FN6: 0 | FO6: 0 | FP6: 0 | FQ6: 0 | FR6: 0 | FS6: 0 | FT6: 0 | FU6: 0 | FV6: 0 | FW6: 0 | FX6: 0 | FY6: 0 | FZ6: 0 | GA6: 0 | GB6: 0 | GC6: 0 | GD6: 0 | GE6: 0 | GF6: 0 | GG6: 0 | GH6: 0 | GI6: 0 | GJ6: 0 | GK6: 0 | GL6: 0 | GM6: 0 | GN6: 0 | GO6: 0
A7: 150+ | B7: 0 | C7: 0 | D7: 0 | E7: 0 | F7: 0 | G7: 0 | H7: 0 | I7: 0 | J7: 0 | K7: 0 | L7: 0 | M7: 0 | N7: 0 | O7: 0 | P7: 0 | Q7: 0 | R7: 0 | S7: 0 | T7: 0 | U7: 0 | V7: 0 | W7: 0 | X7: 0 | Y7: 0 | Z7: 0 | AA7: 0 | AB7: 0 | AC7: 11846.253 | AD7: 1446.1897 | AE7: 776.20746 | AF7: 0 | AG7: 0 | AH7: 12537.552 | AI7: 7570.365 | AJ7: 0 | AK7: 25144.376 | AL7: 7657.6967 | AM7: 6027.4074 | AN7: 52339.547 | AO7: 19482.217 | AP7: 9721.9028 | AQ7: 5242.8678 | AR7: 18926.051 | AS7: 20362.901 | AT7: 9680.3874 | AU7: 8405.7896 | AV7: 15613.8 | AW7: 22870.639 | AX7: 7879.1675 | AY7: 32654.785 | AZ7: 22054.105 | BA7: 33814.548 | BB7: 22608.3 | BC7: 19920.29 | BD7: 46921.446 | BE7: 74587.911 | BF7: 39228.678 | BG7: 46605.578 | BH7: 52173.912 | BI7: 34365.955 | BJ7: 34964.698 | BK7: 57660.576 | BL7: 62868.297 | BM7: 129007.91 | BN7: 117751.58 | BO7: 100304.96 | BP7: 150498.07 | BQ7: 190785.92 | BR7: 139566.12 | BS7: 223390.2 | BT7: 180574.81 | BU7: 185204.33 | BV7: 238046.27 | BW7: 229297.9 | BX7: 250782.07 | BY7: 230510.88 | BZ7: 169930.06 | CA7: 226752.28 | CB7: 238379.71 | CC7: 319535.97 | CD7: 225422.72 | CE7: 273281.22 | CF7: 170339.77 | CG7: 262550.7 | CH7: 301863.01 | CI7: 187700.22 | CJ7: 263198.65 | CK7: 313272.54 | CL7: 286029.28 | CM7: 425003.2 | CN7: 359666.07 | CO7: 417129.54 | CP7: 388565.48 | CQ7: 468694.96 | CR7: 358338.59 | CS7: 611092.51 | CT7: 526386.41 | CU7: 594679.48 | CV7: 665060.81 | CW7: 755644.3 | CX7: 642745.45 | CY7: 675523.12 | CZ7: 1002562.3 | DA7: 912914.44 | DB7: 925628.14 | DC7: 1037847.3 | DD7: 733532.27 | DE7: 1130228.9 | DF7: 1184450.4 | DG7: 912157.46 | DH7: 1422107.7 | DI7: 1350375.8 | DJ7: 1272371.3 | DK7: 1946101.4 | DL7: 1489889.1 | DM7: 1851916 | DN7: 2142274.1 | DO7: 1959822.7 | DP7: 1787783.5 | DQ7: 1827490.2 | DR7: 2147010.7 | DS7: 1621673.5 | DT7: 1878987.2 | DU7: 2049329.8 | DV7: 1824902.7 | DW7: 1832949.9 | DX7: 1703515.3 | DY7: 1985911 | DZ7: 1570422.7 | EA7: 1721087.5 | EB7: 1734252.3 | EC7: 1814973.8 | ED7: 1810167.2 | EE7: 1513054.7 | EF7: 2085473.8 | EG7: 1962932 | EH7: 2106881 | EI7: 2226764.2 | EJ7: 2489038 | EK7: 2834441.1 | EL7: 2157946.7 | EM7: 3143513.5 | EN7: 1031106.1 | EO7: 456143.8 | EP7: 473037.33 | EQ7: 173516.67 | ER7: 122072.93 | ES7: 0 | ET7: 0 | EU7: 0 | EV7: 0 | EW7: 0 | EX7: 0 | EY7: 0 | EZ7: 0 | FA7: 0 | FB7: 0 | FC7: 0 | FD7: 0 | FE7: 0 | FF7: 0 | FG7: 0 | FH7: 0 | FI7: 0 | FJ7: 0 | FK7: 0 | FL7: 0 | FM7: 0 | FN7: 0 | FO7: 0 | FP7: 0 | FQ7: 0 | FR7: 0 | FS7: 0 | FT7: 0 | FU7: 0 | FV7: 0 | FW7: 0 | FX7: 0 | FY7: 0 | FZ7: 0 | GA7: 0 | GB7: 0 | GC7: 0 | GD7: 0 | GE7: 0 | GF7: 0 | GG7: 0 | GH7: 0 | GI7: 0 | GJ7: 0 | GK7: 0 | GL7: 0 | GM7: 0 | GN7: 0 | GO7: 0
