Workbook

Sheet Data
A1: Grade A - Balances | B1: 39234 | C1: 39264 | D1: 39295 | E1: 39326 | F1: 39356 | G1: 39387 | H1: 39417 | I1: 39448 | J1: 39479 | K1: 39508 | L1: 39539 | M1: 39569 | N1: 39600 | O1: 39630 | P1: 39661 | Q1: 39692 | R1: 39722 | S1: 39753 | T1: 39783 | U1: 39814 | V1: 39845 | W1: 39873 | X1: 39904 | Y1: 39934 | Z1: 39965 | AA1: 39995 | AB1: 40026 | AC1: 40057 | AD1: 40087 | AE1: 40118 | AF1: 40148 | AG1: 40179 | AH1: 40210 | AI1: 40238 | AJ1: 40269 | AK1: 40299 | AL1: 40330 | AM1: 40360 | AN1: 40391 | AO1: 40422 | AP1: 40452 | AQ1: 40483 | AR1: 40513 | AS1: 40544 | AT1: 40575 | AU1: 40603 | AV1: 40634 | AW1: 40664 | AX1: 40695 | AY1: 40725 | AZ1: 40756 | BA1: 40787 | BB1: 40817 | BC1: 40848 | BD1: 40878 | BE1: 40909 | BF1: 40940 | BG1: 40969 | BH1: 41000 | BI1: 41030 | BJ1: 41061 | BK1: 41091 | BL1: 41122 | BM1: 41153 | BN1: 41183 | BO1: 41214 | BP1: 41244 | BQ1: 41275 | BR1: 41306 | BS1: 41334 | BT1: 41365 | BU1: 41395 | BV1: 41426 | BW1: 41456 | BX1: 41487 | BY1: 41518 | BZ1: 41548 | CA1: 41579 | CB1: 41609 | CC1: 41640 | CD1: 41671 | CE1: 41699 | CF1: 41730 | CG1: 41760 | CH1: 41791 | CI1: 41821 | CJ1: 41852 | CK1: 41883 | CL1: 41913 | CM1: 41944 | CN1: 41974 | CO1: 42005 | CP1: 42036 | CQ1: 42064 | CR1: 42095 | CS1: 42125 | CT1: 42156 | CU1: 42186 | CV1: 42217 | CW1: 42248 | CX1: 42278 | CY1: 42309 | CZ1: 42339 | DA1: 42370 | DB1: 42401 | DC1: 42430 | DD1: 42461 | DE1: 42491 | DF1: 42522 | DG1: 42552 | DH1: 42583 | DI1: 42614 | DJ1: 42644 | DK1: 42675 | DL1: 42705 | DM1: 42736 | DN1: 42767 | DO1: 42795 | DP1: 42826 | DQ1: 42856 | DR1: 42887 | DS1: 42917 | DT1: 42948 | DU1: 42979 | DV1: 43009 | DW1: 43040 | DX1: 43070 | DY1: 43101 | DZ1: 43132 | EA1: 43160 | EB1: 43191 | EC1: 43221 | ED1: 43252 | EE1: 43282 | EF1: 43313 | EG1: 43344 | EH1: 43374 | EI1: 43405 | EJ1: 43435 | EK1: 43466 | EL1: 43497 | EM1: 43525 | EN1: 43556 | EO1: 43586 | EP1: 43617 | EQ1: 43647 | ER1: 43678 | ES1: 43709 | ET1: 43739 | EU1: 43770 | EV1: 43800 | EW1: 43831 | EX1: 43862 | EY1: 43891 | EZ1: 43922 | FA1: 43952 | FB1: 43983 | FC1: 44013 | FD1: 44044 | FE1: 44075 | FF1: 44105 | FG1: 44136 | FH1: 44166 | FI1: 44197 | FJ1: 44228 | FK1: 44256 | FL1: 44287 | FM1: 44317 | FN1: 44348 | FO1: 44378 | FP1: 44409 | FQ1: 44440 | FR1: 44470 | FS1: 44501 | FT1: 44531 | FU1: 44562 | FV1: 44593 | FW1: 44621 | FX1: 44652 | FY1: 44682 | FZ1: 44713 | GA1: 44743 | GB1: 44774 | GC1: 44805 | GD1: 44835 | GE1: 44866 | GF1: 44896 | GG1: 44927 | GH1: 44958 | GI1: 44986 | GJ1: 45017 | GK1: 45047 | GL1: 45078 | GM1: 45108 | GN1: 45139 | GO1: 45170
A2: Current | B2: 0 | C2: 64050 | D2: 107463.59 | E2: 136251.67 | F2: 180443.53 | G2: 242685.26 | H2: 294141.51 | I2: 556800.25 | J2: 723486.9 | K2: 904548.8 | L2: 993815.62 | M2: 1022577.4 | N2: 1041386.8 | O2: 1116578.4 | P2: 1120338.1 | Q2: 1119545.3 | R2: 1204754 | S2: 1338544.4 | T2: 1640440.6 | U2: 2012185.1 | V2: 2358169.9 | W2: 2787859.3 | X2: 3302487.9 | Y2: 3668220 | Z2: 4209369.1 | AA2: 4734973.4 | AB2: 5355905.1 | AC2: 6081062.6 | AD2: 6762929.7 | AE2: 7510857.4 | AF2: 8286220.2 | AG2: 8990622.8 | AH2: 9640419 | AI2: 10414808 | AJ2: 11099231 | AK2: 12268454 | AL2: 13573264 | AM2: 15100581 | AN2: 15940209 | AO2: 17195064 | AP2: 19221405 | AQ2: 21128473 | AR2: 23983917 | AS2: 26460328 | AT2: 28119775 | AU2: 29757682 | AV2: 31100269 | AW2: 32907838 | AX2: 35091986 | AY2: 37341636 | AZ2: 40645227 | BA2: 45034723 | BB2: 49943237 | BC2: 53903756 | BD2: 56455135 | BE2: 61525583 | BF2: 67664395 | BG2: 74213298 | BH2: 79604152 | BI2: 85496015 | BJ2: 89336288 | BK2: 94081818 | BL2: 1.0155473e+08 | BM2: 1.0854135e+08 | BN2: 1.1502232e+08 | BO2: 1.1997149e+08 | BP2: 1.3069934e+08 | BQ2: 1.4057777e+08 | BR2: 1.5257855e+08 | BS2: 1.6818718e+08 | BT2: 1.8210189e+08 | BU2: 1.906347e+08 | BV2: 1.9954699e+08 | BW2: 2.1080066e+08 | BX2: 2.2120378e+08 | BY2: 2.3071586e+08 | BZ2: 2.4507086e+08 | CA2: 2.7190595e+08 | CB2: 2.9627143e+08 | CC2: 3.1883856e+08 | CD2: 3.3788203e+08 | CE2: 3.5384975e+08 | CF2: 3.7631861e+08 | CG2: 3.9736825e+08 | CH2: 4.1125115e+08 | CI2: 4.4463214e+08 | CJ2: 4.673362e+08 | CK2: 4.7563955e+08 | CL2: 5.5224526e+08 | CM2: 5.8234626e+08 | CN2: 5.8534217e+08 | CO2: 645097670 | CP2: 6.7764975e+08 | CQ2: 7.0665755e+08 | CR2: 7.5845282e+08 | CS2: 8.0481154e+08 | CT2: 8.3706647e+08 | CU2: 9.0710169e+08 | CV2: 9.4845208e+08 | CW2: 9.7394104e+08 | CX2: 1.0532717e+09 | CY2: 1.0955226e+09 | CZ2: 1.1519079e+09 | DA2: 1.1888318e+09 | DB2: 1.2329593e+09 | DC2: 1.3342901e+09 | DD2: 1.3392334e+09 | DE2: 1.3223776e+09 | DF2: 1.3099514e+09 | DG2: 1.2701025e+09 | DH2: 1.2280948e+09 | DI2: 1.179207e+09 | DJ2: 1.1371796e+09 | DK2: 1.0936934e+09 | DL2: 1.0524175e+09 | DM2: 1.0107764e+09 | DN2: 9.6546304e+08 | DO2: 9.3200228e+08 | DP2: 8.8370774e+08 | DQ2: 8.4941515e+08 | DR2: 8.1346356e+08 | DS2: 7.7290412e+08 | DT2: 7.3667678e+08 | DU2: 6.9503841e+08 | DV2: 6.6153919e+08 | DW2: 6.3166732e+08 | DX2: 5.9684289e+08 | DY2: 5.6542324e+08 | DZ2: 5.2373769e+08 | EA2: 4.8744921e+08 | EB2: 4.438859e+08 | EC2: 4.0860016e+08 | ED2: 3.7038543e+08 | EE2: 3.3072807e+08 | EF2: 2.8907246e+08 | EG2: 2.4514382e+08 | EH2: 2.0838549e+08 | EI2: 1.6629112e+08 | EJ2: 1.2932303e+08 | EK2: 93279017 | EL2: 55278589 | EM2: 16800786 | EN2: 1002300.6 | EO2: 958768.58 | EP2: 915973.25 | EQ2: 874303.36 | ER2: 832589.37 | ES2: 791399.32 | ET2: 750334.87 | EU2: 709026.23 | EV2: 667935.03 | EW2: 627416.35 | EX2: 587596.6 | EY2: 547540.61 | EZ2: 508811.15 | FA2: 470965.93 | FB2: 434194.05 | FC2: 399073.82 | FD2: 363963.35 | FE2: 330188.18 | FF2: 297296 | FG2: 265337.21 | FH2: 233594.55 | FI2: 205140.34 | FJ2: 181520.38 | FK2: 158509.85 | FL2: 138530.24 | FM2: 122177.61 | FN2: 107333.16 | FO2: 96277.86 | FP2: 85497.25 | FQ2: 76704.38 | FR2: 69791.77 | FS2: 65628.96 | FT2: 61756.95 | FU2: 58105.84 | FV2: 54431.76 | FW2: 50734.54 | FX2: 47014.06 | FY2: 43270.16 | FZ2: 39502.69 | GA2: 35711.51 | GB2: 31896.47 | GC2: 28057.41 | GD2: 24194.19 | GE2: 20306.66 | GF2: 16876.89 | GG2: 13425.69 | GH2: 9952.95 | GI2: 7676.48 | GJ2: 5816.83 | GK2: 4743.84 | GL2: 3663.83 | GM2: 2576.78 | GN2: 1482.62 | GO2: 381.31
A3: 30+ | B3: 0 | C3: 0 | D3: 0 | E3: 0 | F3: 0 | G3: 0 | H3: 0 | I3: 0 | J3: 0 | K3: 0 | L3: 0 | M3: 0 | N3: 0 | O3: 0 | P3: 0 | Q3: 0 | R3: 0 | S3: 0 | T3: 0 | U3: 0 | V3: 0 | W3: 0 | X3: 0 | Y3: 13804.92 | Z3: 1808.83 | AA3: 1002.26 | AB3: 0 | AC3: 0 | AD3: 14601.75 | AE3: 8842.77 | AF3: 0 | AG3: 29117.12 | AH3: 8938.18 | AI3: 7441.4 | AJ3: 64846.56 | AK3: 23069.62 | AL3: 11774.68 | AM3: 6181.16 | AN3: 22491.22 | AO3: 23590.31 | AP3: 10994.58 | AQ3: 10385.21 | AR3: 18905.39 | AS3: 27903.79 | AT3: 9966.5 | AU3: 39923.73 | AV3: 28059.78 | AW3: 41678.16 | AX3: 25243.4 | AY3: 23089.21 | AZ3: 53863.35 | BA3: 89706.25 | BB3: 47506.53 | BC3: 58819.64 | BD3: 59797.5 | BE3: 41026.85 | BF3: 41196.37 | BG3: 70181.66 | BH3: 76380.69 | BI3: 150779.23 | BJ3: 139755.23 | BK3: 118069.77 | BL3: 176016.47 | BM3: 220941.73 | BN3: 164538.09 | BO3: 265220.96 | BP3: 210175.15 | BQ3: 219052.92 | BR3: 282951.04 | BS3: 271498.82 | BT3: 297649.87 | BU3: 274526.59 | BV3: 204310.05 | BW3: 275021.3 | BX3: 287377.7 | BY3: 381179.56 | BZ3: 279582.73 | CA3: 332866.49 | CB3: 214684.71 | CC3: 326265.69 | CD3: 363695.39 | CE3: 229307.43 | CF3: 319428.8 | CG3: 379673.76 | CH3: 342129.82 | CI3: 512511.41 | CJ3: 459858.84 | CK3: 501483.62 | CL3: 475840.55 | CM3: 587533.16 | CN3: 435586.94 | CO3: 736531.9 | CP3: 642468.87 | CQ3: 737266.91 | CR3: 811283.43 | CS3: 917467.38 | CT3: 787158.12 | CU3: 832297.45 | CV3: 1220484.1 | CW3: 1117420.9 | CX3: 1116056.3 | CY3: 1264515.4 | CZ3: 903031.79 | DA3: 1377682.1 | DB3: 1438557.5 | DC3: 1119483.8 | DD3: 1742795.5 | DE3: 1651720.7 | DF3: 1556205.9 | DG3: 2364392.1 | DH3: 1869370.7 | DI3: 2280237.8 | DJ3: 2648443.1 | DK3: 2426723.3 | DL3: 2182648.8 | DM3: 2262457.7 | DN3: 2668882.8 | DO3: 2037112 | DP3: 2380550.8 | DQ3: 2574914.1 | DR3: 2291906 | DS3: 2321171.9 | DT3: 2173382.5 | DU3: 2535503.9 | DV3: 1993946.7 | DW3: 2232229.6 | DX3: 2211802.1 | DY3: 2280424.6 | DZ3: 2301614.6 | EA3: 1908371.5 | EB3: 2632577.8 | EC3: 2444770.7 | ED3: 2565294.4 | EE3: 2756089.1 | EF3: 3059621.7 | EG3: 3459336.7 | EH3: 2667814.5 | EI3: 3800497.3 | EJ3: 1264926.6 | EK3: 584442.93 | EL3: 591137.38 | EM3: 227919.94 | EN3: 166237.67 | EO3: 0 | EP3: 0 | EQ3: 0 | ER3: 0 | ES3: 0 | ET3: 0 | EU3: 0 | EV3: 0 | EW3: 0 | EX3: 0 | EY3: 0 | EZ3: 0 | FA3: 0 | FB3: 0 | FC3: 0 | FD3: 0 | FE3: 0 | FF3: 0 | FG3: 0 | FH3: 0 | FI3: 0 | FJ3: 0 | FK3: 0 | FL3: 0 | FM3: 0 | FN3: 0 | FO3: 0 | FP3: 0 | FQ3: 0 | FR3: 0 | FS3: 0 | FT3: 0 | FU3: 0 | FV3: 0 | FW3: 0 | FX3: 0 | FY3: 0 | FZ3: 0 | GA3: 0 | GB3: 0 | GC3: 0 | GD3: 0 | GE3: 0 | GF3: 0 | GG3: 0 | GH3: 0 | GI3: 0 | GJ3: 0 | GK3: 0 | GL3: 0 | GM3: 0 | GN3: 0 | GO3: 0
A4: 60+ | B4: 0 | C4: 0 | D4: 0 | E4: 0 | F4: 0 | G4: 0 | H4: 0 | I4: 0 | J4: 0 | K4: 0 | L4: 0 | M4: 0 | N4: 0 | O4: 0 | P4: 0 | Q4: 0 | R4: 0 | S4: 0 | T4: 0 | U4: 0 | V4: 0 | W4: 0 | X4: 0 | Y4: 0 | Z4: 13320.67 | AA4: 1719.04 | AB4: 946.29 | AC4: 0 | AD4: 0 | AE4: 14091.35 | AF4: 8528.41 | AG4: 0 | AH4: 28135.22 | AI4: 8621.11 | AJ4: 7091.76 | AK4: 61754.26 | AL4: 22182.84 | AM4: 11266.98 | AN4: 5949.29 | AO4: 21609.35 | AP4: 22791.91 | AQ4: 10669.78 | AR4: 9783.52 | AS4: 18090.78 | AT4: 26659.45 | AU4: 9450.44 | AV4: 38124.1 | AW4: 26462.53 | AX4: 39732.31 | AY4: 24590.44 | AZ4: 22304.07 | BA4: 52143.83 | BB4: 85962.16 | BC4: 45246.08 | BD4: 55795.93 | BE4: 57909.28 | BF4: 39352.12 | BG4: 39652.39 | BH4: 67082.32 | BI4: 72868.83 | BJ4: 145385.65 | BK4: 134160.06 | BL4: 113630.48 | BM4: 169698.47 | BN4: 213393.02 | BO4: 158230.05 | BP4: 254781.45 | BQ4: 202848.71 | BR4: 210673.49 | BS4: 271796.45 | BT4: 261048.07 | BU4: 286048.07 | BV4: 263626.63 | BW4: 195705.26 | BX4: 263073.82 | BY4: 275187.57 | BZ4: 365922.43 | CA4: 265912.02 | CB4: 317977.34 | CC4: 203478.54 | CD4: 310495.44 | CE4: 347998.88 | CF4: 218816.06 | CG4: 304899.25 | CH4: 363142.75 | CI4: 328243.39 | CJ4: 490848.35 | CK4: 434662.63 | CL4: 480568 | CM4: 454241.32 | CN4: 557776.66 | CO4: 416020.36 | CP4: 703996.44 | CQ4: 613382.02 | CR4: 701853.06 | CS4: 774897.95 | CT4: 877411.86 | CU4: 750910.41 | CV4: 792805.12 | CW4: 1165715.5 | CX4: 1066458.9 | CY4: 1068536.7 | CZ4: 1207697.5 | DA4: 860308.78 | DB4: 1316391.8 | DC4: 1374179.4 | DD4: 1067835.8 | DE4: 1662941.4 | DF4: 1576929.4 | DG4: 1485074.6 | DH4: 2259389.2 | DI4: 1774047.8 | DJ4: 2172785.5 | DK4: 2518742.3 | DL4: 2308573.5 | DM4: 2084501.1 | DN4: 2153494.1 | DO4: 2538084.6 | DP4: 1932708.3 | DQ4: 2254014.4 | DR4: 2442607.1 | DS4: 2173598.1 | DT4: 2198228.4 | DU4: 2054994.4 | DV4: 2394251.1 | DW4: 1887182.4 | DX4: 2103125.7 | DY4: 2090602.4 | DZ4: 2163175.6 | EA4: 2175763.5 | EB4: 1807662.8 | EC4: 2492778.8 | ED4: 2320376.8 | EE4: 2448258.4 | EF4: 2619435.6 | EG4: 2912928 | EH4: 3298300.4 | EI4: 2536404.9 | EJ4: 3633958.5 | EK4: 1203672.5 | EL4: 547589.52 | EM4: 559097.28 | EN4: 214144.51 | EO4: 153631.36 | EP4: 0 | EQ4: 0 | ER4: 0 | ES4: 0 | ET4: 0 | EU4: 0 | EV4: 0 | EW4: 0 | EX4: 0 | EY4: 0 | EZ4: 0 | FA4: 0 | FB4: 0 | FC4: 0 | FD4: 0 | FE4: 0 | FF4: 0 | FG4: 0 | FH4: 0 | FI4: 0 | FJ4: 0 | FK4: 0 | FL4: 0 | FM4: 0 | FN4: 0 | FO4: 0 | FP4: 0 | FQ4: 0 | FR4: 0 | FS4: 0 | FT4: 0 | FU4: 0 | FV4: 0 | FW4: 0 | FX4: 0 | FY4: 0 | FZ4: 0 | GA4: 0 | GB4: 0 | GC4: 0 | GD4: 0 | GE4: 0 | GF4: 0 | GG4: 0 | GH4: 0 | GI4: 0 | GJ4: 0 | GK4: 0 | GL4: 0 | GM4: 0 | GN4: 0 | GO4: 0
A5: 90+ | B5: 0 | C5: 0 | D5: 0 | E5: 0 | F5: 0 | G5: 0 | H5: 0 | I5: 0 | J5: 0 | K5: 0 | L5: 0 | M5: 0 | N5: 0 | O5: 0 | P5: 0 | Q5: 0 | R5: 0 | S5: 0 | T5: 0 | U5: 0 | V5: 0 | W5: 0 | X5: 0 | Y5: 0 | Z5: 0 | AA5: 12832.83 | AB5: 1628.68 | AC5: 889.96 | AD5: 0 | AE5: 0 | AF5: 13577.21 | AG5: 8211.58 | AH5: 0 | AI5: 27145.83 | AJ5: 8302.02 | AK5: 6739.56 | AL5: 58639.11 | AM5: 21289.38 | AN5: 10755.63 | AO5: 5715.62 | AP5: 20721.23 | AQ5: 21987.9 | AR5: 10342.5 | AS5: 9177.54 | AT5: 17270.67 | AU5: 25405.85 | AV5: 8930.54 | AW5: 36312.78 | AX5: 25003.47 | AY5: 37773.15 | AZ5: 23933.62 | BA5: 21514.22 | BB5: 50413.71 | BC5: 82194.5 | BD5: 42970.71 | BE5: 52752.44 | BF5: 56009.33 | BG5: 37699.62 | BH5: 38099.15 | BI5: 63962.45 | BJ5: 69555.17 | BK5: 139959.38 | BL5: 128722.96 | BM5: 109163.55 | BN5: 163339.59 | BO5: 205797.86 | BP5: 151880.83 | BQ5: 244385.04 | BR5: 195473.39 | BS5: 202239.16 | BT5: 260617.62 | BU5: 250531.27 | BV5: 274369.85 | BW5: 252657.66 | BX5: 187045.02 | BY5: 251046.85 | BZ5: 262998.2 | CA5: 350563.25 | CB5: 252342.69 | CC5: 302990.01 | CD5: 192505.97 | CE5: 294620 | CF5: 332656.97 | CG5: 208256.56 | CH5: 291057.9 | CI5: 346505.17 | CJ5: 314264.9 | CK5: 469043.26 | CL5: 409530.85 | CM5: 459511.3 | CN5: 432496.39 | CO5: 527821.75 | CP5: 396624.3 | CQ5: 672919.73 | CR5: 584576.59 | CS5: 666210.2 | CT5: 738272.45 | CU5: 837090.7 | CV5: 714881 | CW5: 753644.61 | CX5: 1110955.6 | CY5: 1015164.3 | CZ5: 1020710.2 | DA5: 1150513.2 | DB5: 818201.01 | DC5: 1254721.1 | DD5: 1310046.5 | DE5: 1015988.5 | DF5: 1582579.9 | DG5: 1501672.6 | DH5: 1413792 | DI5: 2154278.2 | DJ5: 1678295.3 | DK5: 2065090.4 | DL5: 2391925 | DM5: 2190657.4 | DN5: 1986185.2 | DO5: 2044495.4 | DP5: 2406998.5 | DQ5: 1829547.9 | DR5: 2127240.1 | DS5: 2310544.4 | DT5: 2057074.8 | DU5: 2074547.2 | DV5: 1936288.2 | DW5: 2256433.1 | DX5: 1781004.7 | DY5: 1974306.1 | DZ5: 1969998.7 | EA5: 2046425 | EB5: 2051553 | EC5: 1708463.7 | ED5: 2355119.8 | EE5: 2198064.5 | EF5: 2333681.3 | EG5: 2485973.8 | EH5: 2768404.2 | EI5: 3141812.6 | EJ5: 2407723.4 | EK5: 3468453.6 | EL5: 1142914.6 | EM5: 512701.48 | EN5: 529351.1 | EO5: 200412.37 | EP5: 142113.93 | EQ5: 0 | ER5: 0 | ES5: 0 | ET5: 0 | EU5: 0 | EV5: 0 | EW5: 0 | EX5: 0 | EY5: 0 | EZ5: 0 | FA5: 0 | FB5: 0 | FC5: 0 | FD5: 0 | FE5: 0 | FF5: 0 | FG5: 0 | FH5: 0 | FI5: 0 | FJ5: 0 | FK5: 0 | FL5: 0 | FM5: 0 | FN5: 0 | FO5: 0 | FP5: 0 | FQ5: 0 | FR5: 0 | FS5: 0 | FT5: 0 | FU5: 0 | FV5: 0 | FW5: 0 | FX5: 0 | FY5: 0 | FZ5: 0 | GA5: 0 | GB5: 0 | GC5: 0 | GD5: 0 | GE5: 0 | GF5: 0 | GG5: 0 | GH5: 0 | GI5: 0 | GJ5: 0 | GK5: 0 | GL5: 0 | GM5: 0 | GN5: 0 | GO5: 0
A6: 120+ | B6: 0 | C6: 0 | D6: 0 | E6: 0 | F6: 0 | G6: 0 | H6: 0 | I6: 0 | J6: 0 | K6: 0 | L6: 0 | M6: 0 | N6: 0 | O6: 0 | P6: 0 | Q6: 0 | R6: 0 | S6: 0 | T6: 0 | U6: 0 | V6: 0 | W6: 0 | X6: 0 | Y6: 0 | Z6: 0 | AA6: 0 | AB6: 12341.36 | AC6: 1537.73 | AD6: 833.27 | AE6: 0 | AF6: 0 | AG6: 13059.28 | AH6: 7892.23 | AI6: 0 | AJ6: 26148.9 | AK6: 7980.89 | AL6: 6384.78 | AM6: 55500.93 | AN6: 20389.19 | AO6: 10240.62 | AP6: 5480.15 | AQ6: 19826.81 | AR6: 21178.24 | AS6: 10012.71 | AT6: 8793.08 | AU6: 16445.03 | AV6: 24142.94 | AW6: 8406.8 | AX6: 34489.7 | AY6: 23534.02 | AZ6: 35800.6 | BA6: 23272.92 | BB6: 20719.64 | BC6: 48672.94 | BD6: 78403.14 | BE6: 41105.6 | BF6: 49689.04 | BG6: 54097.56 | BH6: 36037.58 | BI6: 36536.61 | BJ6: 60821.91 | BK6: 66221.7 | BL6: 134500.2 | BM6: 123253.53 | BN6: 104668.82 | BO6: 156939.54 | BP6: 198314.81 | BQ6: 145490.14 | BR6: 233921.43 | BS6: 188048.87 | BT6: 193749.56 | BU6: 249367.71 | BV6: 239948.03 | BW6: 262614.68 | BX6: 241619.22 | BY6: 178328.96 | BZ6: 238939.85 | CA6: 250729.09 | CB6: 335101.32 | CC6: 238685.06 | CD6: 288184.46 | CE6: 181459.88 | CF6: 278638.66 | CG6: 317215.44 | CH6: 197779.3 | CI6: 277124.96 | CJ6: 329760.34 | CK6: 300193.74 | CL6: 447095.2 | CM6: 384678.57 | CN6: 438312.55 | CO6: 410604.77 | CP6: 497947.09 | CQ6: 377544.63 | CR6: 641795.17 | CS6: 555578.48 | CT6: 630560.07 | CU6: 701787.04 | CV6: 796502.11 | CW6: 678931.6 | CX6: 714226.8 | CY6: 1056151.2 | CZ6: 963889.18 | DA6: 972574.87 | DB6: 1094361.4 | DC6: 775824.21 | DD6: 1192667.6 | DE6: 1247448.1 | DF6: 963856.14 | DG6: 1502133.9 | DH6: 1426258.9 | DI6: 1342706.8 | DJ6: 2049560.8 | DK6: 1583310.6 | DL6: 1957622.4 | DM6: 2267087 | DN6: 2074347.2 | DO6: 1887280.5 | DP6: 1935586.8 | DQ6: 2276892.7 | DR6: 1725767.9 | DS6: 2000885.4 | DT6: 2179760.8 | DU6: 1941333.4 | DV6: 1952333.3 | DW6: 1819914.6 | DX6: 2121345.7 | DY6: 1674493.5 | DZ6: 1847006.5 | EA6: 1851731.7 | EB6: 1929957.3 | EC6: 1930270.9 | ED6: 1610430.9 | EE6: 2219626 | EF6: 2078949.9 | EG6: 2219692.9 | EH6: 2352567.1 | EI6: 2627674.9 | EJ6: 2987682.9 | EK6: 2281522.3 | EL6: 3305468.7 | EM6: 1085326.8 | EN6: 482716.72 | EO6: 500789.29 | EP6: 186926.91 | EQ6: 132033.66 | ER6: 0 | ES6: 0 | ET6: 0 | EU6: 0 | EV6: 0 | EW6: 0 | EX6: 0 | EY6: 0 | EZ6: 0 | FA6: 0 | FB6: 0 | FC6: 0 | FD6: 0 | FE6: 0 | FF6: 0 | FG6: 0 | FH6: 0 | FI6: 0 | FJ6: 0 | FK6: 0 | FL6: 0 | FM6: 0 | FN6: 0 | FO6: 0 | FP6: 0 | FQ6: 0 | FR6: 0 | FS6: 0 | FT6: 0 | FU6: 0 | FV6: 0 | FW6: 0 | FX6: 0 | FY6: 0 | FZ6: 0 | GA6: 0 | GB6: 0 | GC6: 0 | GD6: 0 | GE6: 0 | GF6: 0 | GG6: 0 | GH6: 0 | GI6: 0 | GJ6: 0 | GK6: 0 | GL6: 0 | GM6: 0 | GN6: 0 | GO6: 0
A7: 150+ | B7: 0 | C7: 0 | D7: 0 | E7: 0 | F7: 0 | G7: 0 | H7: 0 | I7: 0 | J7: 0 | K7: 0 | L7: 0 | M7: 0 | N7: 0 | O7: 0 | P7: 0 | Q7: 0 | R7: 0 | S7: 0 | T7: 0 | U7: 0 | V7: 0 | W7: 0 | X7: 0 | Y7: 0 | Z7: 0 | AA7: 0 | AB7: 0 | AC7: 11846.25 | AD7: 1446.19 | AE7: 776.21 | AF7: 0 | AG7: 0 | AH7: 12537.55 | AI7: 7570.37 | AJ7: 0 | AK7: 25144.38 | AL7: 7657.7 | AM7: 6027.41 | AN7: 52339.55 | AO7: 19482.22 | AP7: 9721.9 | AQ7: 5242.87 | AR7: 18926.05 | AS7: 20362.9 | AT7: 9680.39 | AU7: 8405.79 | AV7: 15613.8 | AW7: 22870.64 | AX7: 7879.17 | AY7: 32654.79 | AZ7: 22054.1 | BA7: 33814.55 | BB7: 22608.3 | BC7: 19920.29 | BD7: 46921.45 | BE7: 74587.91 | BF7: 39228.68 | BG7: 46605.58 | BH7: 52173.91 | BI7: 34365.95 | BJ7: 34964.7 | BK7: 57660.58 | BL7: 62868.3 | BM7: 129007.91 | BN7: 117751.58 | BO7: 100304.96 | BP7: 150498.07 | BQ7: 190785.92 | BR7: 139566.12 | BS7: 223390.2 | BT7: 180574.81 | BU7: 185204.33 | BV7: 238046.27 | BW7: 229297.9 | BX7: 250782.07 | BY7: 230510.88 | BZ7: 169930.06 | CA7: 226752.28 | CB7: 238379.71 | CC7: 319535.97 | CD7: 225422.72 | CE7: 273281.22 | CF7: 170339.77 | CG7: 262550.7 | CH7: 301863.01 | CI7: 187700.22 | CJ7: 263198.65 | CK7: 313272.54 | CL7: 286029.28 | CM7: 425003.2 | CN7: 359666.07 | CO7: 417129.54 | CP7: 388565.48 | CQ7: 468694.96 | CR7: 358338.59 | CS7: 611092.51 | CT7: 526386.41 | CU7: 594679.48 | CV7: 665060.81 | CW7: 755644.3 | CX7: 642745.45 | CY7: 675523.12 | CZ7: 1002562.3 | DA7: 912914.44 | DB7: 925628.14 | DC7: 1037847.3 | DD7: 733532.27 | DE7: 1130228.9 | DF7: 1184450.4 | DG7: 912157.46 | DH7: 1422107.7 | DI7: 1350375.8 | DJ7: 1272371.3 | DK7: 1946101.4 | DL7: 1489889.1 | DM7: 1851916 | DN7: 2142274.1 | DO7: 1959822.7 | DP7: 1787783.5 | DQ7: 1827490.2 | DR7: 2147010.7 | DS7: 1621673.5 | DT7: 1878987.2 | DU7: 2049329.8 | DV7: 1824902.7 | DW7: 1832949.9 | DX7: 1703515.3 | DY7: 1985911 | DZ7: 1570422.7 | EA7: 1721087.5 | EB7: 1734252.3 | EC7: 1814973.8 | ED7: 1810167.2 | EE7: 1513054.7 | EF7: 2085473.8 | EG7: 1962932 | EH7: 2106881 | EI7: 2226764.2 | EJ7: 2489038 | EK7: 2834441.1 | EL7: 2157946.7 | EM7: 3143513.5 | EN7: 1031106.1 | EO7: 456143.8 | EP7: 473037.33 | EQ7: 173516.67 | ER7: 122072.93 | ES7: 0 | ET7: 0 | EU7: 0 | EV7: 0 | EW7: 0 | EX7: 0 | EY7: 0 | EZ7: 0 | FA7: 0 | FB7: 0 | FC7: 0 | FD7: 0 | FE7: 0 | FF7: 0 | FG7: 0 | FH7: 0 | FI7: 0 | FJ7: 0 | FK7: 0 | FL7: 0 | FM7: 0 | FN7: 0 | FO7: 0 | FP7: 0 | FQ7: 0 | FR7: 0 | FS7: 0 | FT7: 0 | FU7: 0 | FV7: 0 | FW7: 0 | FX7: 0 | FY7: 0 | FZ7: 0 | GA7: 0 | GB7: 0 | GC7: 0 | GD7: 0 | GE7: 0 | GF7: 0 | GG7: 0 | GH7: 0 | GI7: 0 | GJ7: 0 | GK7: 0 | GL7: 0 | GM7: 0 | GN7: 0 | GO7: 0
A8: 180+ | B8: 0 | C8: 0 | D8: 0 | E8: 0 | F8: 0 | G8: 0 | H8: 0 | I8: 0 | J8: 0 | K8: 0 | L8: 0 | M8: 0 | N8: 0 | O8: 0 | P8: 0 | Q8: 0 | R8: 0 | S8: 0 | T8: 0 | U8: 0 | V8: 0 | W8: 0 | X8: 0 | Y8: 0 | Z8: 0 | AA8: 0 | AB8: 0 | AC8: 0 | AD8: 11347.47 | AE8: 1354.06 | AF8: 718.78 | AG8: 0 | AH8: 0 | AI8: 12011.98 | AJ8: 7245.95 | AK8: 0 | AL8: 24132.19 | AM8: 7332.44 | AN8: 5667.41 | AO8: 49154.8 | AP8: 18568.41 | AQ8: 9199.46 | AR8: 5003.75 | AS8: 18018.91 | AT8: 19541.83 | AU8: 9345.52 | AV8: 8015.64 | AW8: 14776.96 | AX8: 21588.88 | AY8: 7347.63 | AZ8: 30807.95 | BA8: 20563.65 | BB8: 31814.91 | BC8: 21939.75 | BD8: 19116.14 | BE8: 45159.16 | BF8: 70748.66 | BG8: 37339.88 | BH8: 43869.88 | BI8: 50238.3 | BJ8: 32684.69 | BK8: 33383.36 | BL8: 54478.3 | BM8: 59494.83 | BN8: 123482.31 | BO8: 112216.92 | BP8: 95914.13 | BQ8: 144014.9 | BR8: 183210.89 | BS8: 133603.53 | BT8: 212790.91 | BU8: 173267.47 | BV8: 176603.09 | BW8: 226652.84 | BX8: 218580.46 | BY8: 239308.39 | BZ8: 219863.96 | CA8: 161476.94 | CB8: 214483.6 | CC8: 225949.53 | CD8: 303866.47 | CE8: 212073.7 | CF8: 258279.63 | CG8: 159439.79 | CH8: 246355.41 | CI8: 286499.91 | CJ8: 177555.27 | CK8: 249179.99 | CL8: 297046.34 | CM8: 271770.89 | CN8: 402766.32 | CO8: 334874.96 | CP8: 395803.71 | CQ8: 366438.9 | CR8: 439740.59 | CS8: 339196.18 | CT8: 580188.34 | CU8: 497630.41 | CV8: 558629.25 | CW8: 628469.49 | CX8: 714734.48 | CY8: 606787.7 | CZ8: 636565.11 | DA8: 949210.59 | DB8: 862795.23 | DC8: 878697.12 | DD8: 981730.66 | DE8: 692402.51 | DF8: 1068769.7 | DG8: 1121050.8 | DH8: 860508.06 | DI8: 1341572.3 | DJ8: 1274890.5 | DK8: 1201921.8 | DL8: 1842886.3 | DM8: 1397878.9 | DN8: 1747346.4 | DO8: 2018952.9 | DP8: 1844985.5 | DQ8: 1688962.9 | DR8: 1719958.6 | DS8: 2016852 | DT8: 1521254.8 | DU8: 1759779.9 | DV8: 1918863.8 | DW8: 1708653.3 | DX8: 1713260.1 | DY8: 1589183.4 | DZ8: 1853742 | EA8: 1467740.9 | EB8: 1597725 | EC8: 1621239.2 | ED8: 1701117.5 | EE8: 1692504.1 | EF8: 1416698.6 | EG8: 1953196.7 | EH8: 1847808.8 | EI8: 1997252.4 | EJ8: 2103242.4 | EK8: 2350779.2 | EL8: 2686422.5 | EM8: 2040760.7 | EN8: 2988225.6 | EO8: 980221 | EP8: 429409.66 | EQ8: 445840.29 | ER8: 160847.01 | ES8: 112442.96 | ET8: 0 | EU8: 0 | EV8: 0 | EW8: 0 | EX8: 0 | EY8: 0 | EZ8: 0 | FA8: 0 | FB8: 0 | FC8: 0 | FD8: 0 | FE8: 0 | FF8: 0 | FG8: 0 | FH8: 0 | FI8: 0 | FJ8: 0 | FK8: 0 | FL8: 0 | FM8: 0 | FN8: 0 | FO8: 0 | FP8: 0 | FQ8: 0 | FR8: 0 | FS8: 0 | FT8: 0 | FU8: 0 | FV8: 0 | FW8: 0 | FX8: 0 | FY8: 0 | FZ8: 0 | GA8: 0 | GB8: 0 | GC8: 0 | GD8: 0 | GE8: 0 | GF8: 0 | GG8: 0 | GH8: 0 | GI8: 0 | GJ8: 0 | GK8: 0 | GL8: 0 | GM8: 0 | GN8: 0 | GO8: 0
A9: GCO | B9: 0 | C9: 0 | D9: 0 | E9: 0 | F9: 0 | G9: 0 | H9: 0 | I9: 0 | J9: 0 | K9: 0 | L9: 0 | M9: 0 | N9: 0 | O9: 0 | P9: 0 | Q9: 0 | R9: 0 | S9: 0 | T9: 0 | U9: 0 | V9: 0 | W9: 0 | X9: 0 | Y9: 0 | Z9: 0 | AA9: 0 | AB9: 0 | AC9: 0 | AD9: 0 | AE9: 10844.98 | AF9: 1261.34 | AG9: 660.98 | AH9: 0 | AI9: 0 | AJ9: 11482.55 | AK9: 6918.97 | AL9: 0 | AM9: 23112.29 | AN9: 7005.1 | AO9: 5304.78 | AP9: 45946.5 | AQ9: 17647.71 | AR9: 8673.27 | AS9: 4762.79 | AT9: 17105.33 | AU9: 18714.99 | AV9: 9008.09 | AW9: 7622.6 | AX9: 13934.47 | AY9: 20297.6 | AZ9: 6812.14 | BA9: 28949.12 | BB9: 19062.57 | BC9: 29801.59 | BD9: 21267.25 | BE9: 18307.17 | BF9: 43386.02 | BG9: 66885.25 | BH9: 35439.12 | BI9: 41116.75 | BJ9: 48290.65 | BK9: 30993.72 | BL9: 31792.55 | BM9: 51274.95 | BN9: 56101.19 | BO9: 117923.2 | BP9: 106649.33 | BQ9: 91496.15 | BR9: 137489.76 | BS9: 175589.45 | BT9: 127602.1 | BU9: 202123.09 | BV9: 165911.22 | BW9: 167945.47 | BX9: 215373.62 | BY9: 207795.28 | BZ9: 227759.05 | CA9: 209703.08 | CB9: 152969.26 | CC9: 202287.43 | CD9: 213859.21 | CE9: 288092.14 | CF9: 198637.42 | CG9: 243179.02 | CH9: 149083.81 | CI9: 230052.06 | CJ9: 271037.21 | CK9: 167344 | CL9: 235194.37 | CM9: 280949.27 | CN9: 257417.95 | CO9: 380383.57 | CP9: 312245.51 | CQ9: 374379.72 | CR9: 344162.96 | CS9: 411049.88 | CT9: 320398.01 | CU9: 549246.37 | CV9: 468852.71 | CW9: 522771.43 | CX9: 592041.72 | CY9: 673876.41 | CZ9: 571049.55 | DA9: 598415.25 | DB9: 895510.72 | DC9: 814298.58 | DD9: 832548.54 | DE9: 926725.14 | DF9: 651387.23 | DG9: 1007944.7 | DH9: 1058373.3 | DI9: 808534.33 | DJ9: 1261265 | DK9: 1200275.7 | DL9: 1132437.6 | DM9: 1740864.5 | DN9: 1307167.1 | DO9: 1643128.8 | DP9: 1896809.2 | DQ9: 1731624.5 | DR9: 1592681.8 | DS9: 1612339.7 | DT9: 1888311.8 | DU9: 1422513.9 | DV9: 1640382.2 | DW9: 1790982 | DX9: 1594160.3 | DY9: 1593590.9 | DZ9: 1477115 | EA9: 1725067.1 | EB9: 1367697.6 | EC9: 1479878.3 | ED9: 1510497.8 | EE9: 1590639.6 | EF9: 1576126.8 | EG9: 1321797.3 | EH9: 1824013.7 | EI9: 1736698 | EJ9: 1889358.9 | EK9: 1983230.2 | EL9: 2215922.7 | EM9: 2542491.5 | EN9: 1928744.1 | EO9: 2838176.8 | EP9: 930035.98 | EQ9: 404346.98 | ER9: 419475.03 | ES9: 148103.06 | ET9: 103018.37 | EU9: 0 | EV9: 0 | EW9: 0 | EX9: 0 | EY9: 0 | EZ9: 0 | FA9: 0 | FB9: 0 | FC9: 0 | FD9: 0 | FE9: 0 | FF9: 0 | FG9: 0 | FH9: 0 | FI9: 0 | FJ9: 0 | FK9: 0 | FL9: 0 | FM9: 0 | FN9: 0 | FO9: 0 | FP9: 0 | FQ9: 0 | FR9: 0 | FS9: 0 | FT9: 0 | FU9: 0 | FV9: 0 | FW9: 0 | FX9: 0 | FY9: 0 | FZ9: 0 | GA9: 0 | GB9: 0 | GC9: 0 | GD9: 0 | GE9: 0 | GF9: 0 | GG9: 0 | GH9: 0 | GI9: 0 | GJ9: 0 | GK9: 0 | GL9: 0 | GM9: 0 | GN9: 0 | GO9: 0
A11: Grade A - Flow Rates
A12: FR 30 | D12: 0 | E12: 0 | F12: 0 | G12: 0 | H12: 0 | I12: 0 | J12: 0 | K12: 0 | L12: 0 | M12: 0 | N12: 0 | O12: 0 | P12: 0 | Q12: 0 | R12: 0 | S12: 0 | T12: 0 | U12: 0 | V12: 0 | W12: 0 | X12: 0 | Y12: 0.00418 | Z12: 0.000493 | AA12: 0.000238 | AB12: 0 | AC12: 0 | AD12: 0.002401 | AE12: 0.001308 | AF12: 0 | AG12: 0.003514 | AH12: 0.000994 | AI12: 0.000772 | AJ12: 0.006226 | AK12: 0.002078 | AL12: 0.00096 | AM12: 0.000455 | AN12: 0.001489 | AO12: 0.00148 | AP12: 0.000639 | AQ12: 0.00054 | AR12: 0.000895 | AS12: 0.001163 | AT12: 0.000377 | AU12: 0.00142 | AV12: 0.000943 | AW12: 0.00134 | AX12: 0.000767 | AY12: 0.000658 | AZ12: 0.001442 | BA12: 0.002207 | BB12: 0.001055 | BC12: 0.001178 | BD12: 0.001109 | BE12: 0.000727 | BF12: 0.00067 | BG12: 0.001037 | BH12: 0.001029 | BI12: 0.001894 | BJ12: 0.001635 | BK12: 0.001322 | BL12: 0.001871 | BM12: 0.002176 | BN12: 0.001516 | BO12: 0.002306 | BP12: 0.001752 | BQ12: 0.001676 | BR12: 0.002013 | BS12: 0.001779 | BT12: 0.00177 | BU12: 0.001508 | BV12: 0.001072 | BW12: 0.001378 | BX12: 0.001363 | BY12: 0.001723 | BZ12: 0.001212 | CA12: 0.001358 | CB12: 0.00079 | CC12: 0.001101 | CD12: 0.001141 | CE12: 0.000679 | CF12: 0.000903 | CG12: 0.001009 | CH12: 0.000861 | CI12: 0.001246 | CJ12: 0.001034 | CK12: 0.001073 | CL12: 0.001 | CM12: 0.001064 | CN12: 0.000748 | CO12: 0.001258 | CP12: 0.000996 | CQ12: 0.001088 | CR12: 0.001148 | CS12: 0.00121 | CT12: 0.000978 | CU12: 0.000994 | CV12: 0.001345 | CW12: 0.001178 | CX12: 0.001146 | CY12: 0.001201 | CZ12: 0.000824 | DA12: 0.001196 | DB12: 0.00121 | DC12: 0.000908 | DD12: 0.001306 | DE12: 0.001233 | DF12: 0.001177 | DG12: 0.001805 | DH12: 0.001472 | DI12: 0.001857 | DJ12: 0.002246 | DK12: 0.002134 | DL12: 0.001996 | DM12: 0.00215 | DN12: 0.00264 | DO12: 0.00211 | DP12: 0.002554 | DQ12: 0.002914 | DR12: 0.002698 | DS12: 0.002853 | DT12: 0.002812 | DU12: 0.003442 | DV12: 0.002869 | DW12: 0.003374 | DX12: 0.003502 | DY12: 0.003821 | DZ12: 0.004071 | EA12: 0.003644 | EB12: 0.005401 | EC12: 0.005508 | ED12: 0.006278 | EE12: 0.007441 | EF12: 0.009251 | EG12: 0.011967 | EH12: 0.010883 | EI12: 0.018238 | EJ12: 0.007607 | EK12: 0.004519 | EL12: 0.006337 | EM12: 0.004123 | EN12: 0.009895 | EO12: 0 | EP12: 0 | EQ12: 0 | ER12: 0 | ES12: 0 | ET12: 0 | EU12: 0 | EV12: 0 | EW12: 0 | EX12: 0 | EY12: 0 | EZ12: 0 | FA12: 0 | FB12: 0 | FC12: 0 | FD12: 0 | FE12: 0 | FF12: 0 | FG12: 0 | FH12: 0 | FI12: 0 | FJ12: 0 | FK12: 0 | FL12: 0 | FM12: 0 | FN12: 0 | FO12: 0 | FP12: 0 | FQ12: 0 | FR12: 0 | FS12: 0 | FT12: 0 | FU12: 0 | FV12: 0 | FW12: 0 | FX12: 0 | FY12: 0 | FZ12: 0 | GA12: 0 | GB12: 0 | GC12: 0 | GD12: 0 | GE12: 0 | GF12: 0 | GG12: 0 | GH12: 0 | GI12: 0 | GJ12: 0 | GK12: 0 | GL12: 0 | GM12: 0 | GN12: 0 | GO12: 0
A13: FR 60 | Z13: 0.964922 | AA13: 0.950362 | AB13: 0.944157 | AE13: 0.965046 | AF13: 0.964451 | AH13: 0.966277 | AI13: 0.964527 | AJ13: 0.953015 | AK13: 0.952314 | AL13: 0.961561 | AM13: 0.956882 | AN13: 0.962487 | AO13: 0.960791 | AP13: 0.966156 | AQ13: 0.970459 | AR13: 0.942063 | AS13: 0.956911 | AT13: 0.955406 | AU13: 0.94822 | AV13: 0.954923 | AW13: 0.943077 | AX13: 0.953312 | AY13: 0.974133 | AZ13: 0.965996 | BA13: 0.968076 | BB13: 0.958263 | BC13: 0.952418 | BD13: 0.948594 | BE13: 0.968423 | BF13: 0.95918 | BG13: 0.962521 | BH13: 0.955838 | BI13: 0.954022 | BJ13: 0.964229 | BK13: 0.959964 | BL13: 0.962401 | BM13: 0.964106 | BN13: 0.965834 | BO13: 0.961662 | BP13: 0.960638 | BQ13: 0.965141 | BR13: 0.961747 | BS13: 0.960578 | BT13: 0.961507 | BU13: 0.961022 | BV13: 0.960295 | BW13: 0.957884 | BX13: 0.956558 | BY13: 0.957582 | BZ13: 0.959974 | CA13: 0.951103 | CB13: 0.95527 | CC13: 0.947802 | CD13: 0.951664 | CE13: 0.956842 | CF13: 0.954248 | CG13: 0.954514 | CH13: 0.95646 | CI13: 0.959412 | CJ13: 0.957732 | CK13: 0.945209 | CL13: 0.958293 | CM13: 0.954608 | CN13: 0.949354 | CO13: 0.95508 | CP13: 0.955826 | CQ13: 0.954726 | CR13: 0.951966 | CS13: 0.955151 | CT13: 0.956341 | CU13: 0.953951 | CV13: 0.95255 | CW13: 0.955126 | CX13: 0.954393 | CY13: 0.957422 | CZ13: 0.955067 | DA13: 0.952689 | DB13: 0.955512 | DC13: 0.955248 | DD13: 0.953864 | DE13: 0.95418 | DF13: 0.954719 | DG13: 0.954292 | DH13: 0.95559 | DI13: 0.949008 | DJ13: 0.952877 | DK13: 0.951028 | DL13: 0.951313 | DM13: 0.955033 | DN13: 0.951838 | DO13: 0.950991 | DP13: 0.948749 | DQ13: 0.946846 | DR13: 0.948617 | DS13: 0.94838 | DT13: 0.947034 | DU13: 0.945528 | DV13: 0.94429 | DW13: 0.946456 | DX13: 0.942164 | DY13: 0.945203 | DZ13: 0.948585 | EA13: 0.945321 | EB13: 0.947228 | EC13: 0.946897 | ED13: 0.949118 | EE13: 0.954377 | EF13: 0.950418 | EG13: 0.952055 | EH13: 0.953449 | EI13: 0.950743 | EJ13: 0.95618 | EK13: 0.951575 | EL13: 0.936943 | EM13: 0.945799 | EN13: 0.93956 | EO13: 0.924167
A14: FR 90 | AA14: 0.963377 | AB14: 0.947432 | AF14: 0.963513 | AG14: 0.962849 | AI14: 0.964835 | AJ14: 0.962987 | AK14: 0.950337 | AL14: 0.949556 | AM14: 0.959723 | AN14: 0.954616 | AO14: 0.960724 | AP14: 0.958901 | AQ14: 0.964724 | AR14: 0.969326 | AS14: 0.938061 | AT14: 0.954667 | AU14: 0.952977 | AV14: 0.944987 | AW14: 0.952489 | AX14: 0.944863 | AY14: 0.950691 | AZ14: 0.97329 | BA14: 0.964587 | BB14: 0.96682 | BC14: 0.956171 | BD14: 0.949711 | BE14: 0.945453 | BF14: 0.967191 | BG14: 0.958007 | BH14: 0.960829 | BI14: 0.953492 | BJ14: 0.954526 | BK14: 0.962677 | BL14: 0.959473 | BM14: 0.960689 | BN14: 0.962528 | BO14: 0.964408 | BP14: 0.959873 | BQ14: 0.959195 | BR14: 0.963641 | BS14: 0.959965 | BT14: 0.958871 | BU14: 0.959713 | BV14: 0.959174 | BW14: 0.958392 | BX14: 0.955749 | BY14: 0.954283 | BZ14: 0.955705 | CA14: 0.958026 | CB14: 0.948971 | CC14: 0.952867 | CD14: 0.946075 | CE14: 0.948871 | CF14: 0.955914 | CG14: 0.951743 | CH14: 0.954604 | CI14: 0.954184 | CJ14: 0.957414 | CK14: 0.955577 | CL14: 0.942181 | CM14: 0.956184 | CN14: 0.952129 | CO14: 0.946296 | CP14: 0.953377 | CQ14: 0.955857 | CR14: 0.953038 | CS14: 0.949216 | CT14: 0.952735 | CU14: 0.954045 | CV14: 0.952019 | CW14: 0.950605 | CX14: 0.953025 | CY14: 0.951902 | CZ14: 0.955241 | DA14: 0.95265 | DB14: 0.951055 | DC14: 0.953152 | DD14: 0.95333 | DE14: 0.951446 | DF14: 0.951675 | DG14: 0.952276 | DH14: 0.952001 | DI14: 0.953478 | DJ14: 0.946026 | DK14: 0.950435 | DL14: 0.949651 | DM14: 0.948923 | DN14: 0.952835 | DO14: 0.949385 | DP14: 0.948352 | DQ14: 0.946624 | DR14: 0.943756 | DS14: 0.945934 | DT14: 0.946392 | DU14: 0.943736 | DV14: 0.942235 | DW14: 0.942438 | DX14: 0.943737 | DY14: 0.938749 | DZ14: 0.942311 | EA14: 0.946028 | EB14: 0.942912 | EC14: 0.945123 | ED14: 0.944777 | EE14: 0.947288 | EF14: 0.953201 | EG14: 0.949049 | EH14: 0.950385 | EI14: 0.952555 | EJ14: 0.949266 | EK14: 0.954456 | EL14: 0.949523 | EM14: 0.936288 | EN14: 0.946796 | EO14: 0.935874 | EP14: 0.925032
A15: FR 120 | AB15: 0.961703 | AC15: 0.944157 | AG15: 0.961853 | AH15: 0.961111 | AJ15: 0.963275 | AK15: 0.961319 | AL15: 0.947359 | AM15: 0.946483 | AN15: 0.957716 | AO15: 0.952117 | AP15: 0.958803 | AQ15: 0.956836 | AR15: 0.963177 | AS15: 0.968113 | AT15: 0.958109 | AU15: 0.952194 | AV15: 0.95029 | AW15: 0.941353 | AX15: 0.949795 | AY15: 0.94123 | AZ15: 0.947779 | BA15: 0.972394 | BB15: 0.963067 | BC15: 0.96547 | BD15: 0.953873 | BE15: 0.956596 | BF15: 0.941929 | BG15: 0.965867 | BH15: 0.955914 | BI15: 0.958987 | BJ15: 0.9509 | BK15: 0.952074 | BL15: 0.960995 | BM15: 0.95751 | BN15: 0.958826 | BO15: 0.960818 | BP15: 0.963639 | BQ15: 0.957923 | BR15: 0.957184 | BS15: 0.962018 | BT15: 0.958022 | BU15: 0.956834 | BV15: 0.957757 | BW15: 0.957156 | BX15: 0.956311 | BY15: 0.953401 | BZ15: 0.951774 | CA15: 0.953349 | CB15: 0.955894 | CC15: 0.945877 | CD15: 0.951135 | CE15: 0.942619 | CF15: 0.945756 | CG15: 0.953581 | CH15: 0.949691 | CI15: 0.95213 | CJ15: 0.951675 | CK15: 0.955225 | CL15: 0.953207 | CM15: 0.939315 | CN15: 0.953867 | CO15: 0.949383 | CP15: 0.9434 | CQ15: 0.951895 | CR15: 0.953747 | CS15: 0.950395 | CT15: 0.946488 | CU15: 0.95058 | CV15: 0.951512 | CW15: 0.949713 | CX15: 0.947697 | CY15: 0.950669 | CZ15: 0.949491 | DA15: 0.952841 | DB15: 0.951194 | DC15: 0.948207 | DD15: 0.950544 | DE15: 0.952217 | DF15: 0.948688 | DG15: 0.949168 | DH15: 0.94978 | DI15: 0.94972 | DJ15: 0.951391 | DK15: 0.943404 | DL15: 0.94796 | DM15: 0.947809 | DN15: 0.946906 | DO15: 0.950204 | DP15: 0.946731 | DQ15: 0.945947 | DR15: 0.943276 | DS15: 0.940602 | DT15: 0.943397 | DU15: 0.943735 | DV15: 0.941089 | DW15: 0.939899 | DX15: 0.940132 | DY15: 0.940196 | DZ15: 0.935522 | EA15: 0.939966 | EB15: 0.943087 | EC15: 0.940883 | ED15: 0.942619 | EE15: 0.942468 | EF15: 0.945809 | EG15: 0.951155 | EH15: 0.946336 | EI15: 0.949166 | EJ15: 0.950942 | EK15: 0.947585 | EL15: 0.953009 | EM15: 0.949613 | EN15: 0.941516 | EO15: 0.946044 | EP15: 0.932711 | EQ15: 0.929069
A16: FR 150 | AC16: 0.959882 | AD16: 0.940472 | AH16: 0.960049 | AI16: 0.959217 | AK16: 0.961584 | AL16: 0.959505 | AM16: 0.944027 | AN16: 0.943039 | AO16: 0.955517 | AP16: 0.949347 | AQ16: 0.956701 | AR16: 0.954569 | AS16: 0.961501 | AT16: 0.96681 | AU16: 0.955955 | AV16: 0.949454 | AW16: 0.947301 | AX16: 0.937238 | AY16: 0.946798 | AZ16: 0.937116 | BA16: 0.944525 | BB16: 0.971443 | BC16: 0.961421 | BD16: 0.964015 | BE16: 0.951338 | BF16: 0.954339 | BG16: 0.937945 | BH16: 0.964441 | BI16: 0.953614 | BJ16: 0.956977 | BK16: 0.948023 | BL16: 0.949361 | BM16: 0.959165 | BN16: 0.955361 | BO16: 0.958308 | BP16: 0.958956 | BQ16: 0.962036 | BR16: 0.959282 | BS16: 0.95498 | BT16: 0.960255 | BU16: 0.955895 | BV16: 0.954599 | BW16: 0.955615 | BX16: 0.954943 | BY16: 0.954025 | BZ16: 0.952902 | CA16: 0.948993 | CB16: 0.950746 | CC16: 0.95355 | CD16: 0.944436 | CE16: 0.948286 | CF16: 0.938719 | CG16: 0.942262 | CH16: 0.951603 | CI16: 0.949039 | CJ16: 0.949747 | CK16: 0.950001 | CL16: 0.952816 | CM16: 0.950588 | CN16: 0.934978 | CO16: 0.951671 | CP16: 0.946325 | CQ16: 0.941255 | CR16: 0.949129 | CS16: 0.952161 | CT16: 0.947456 | CU16: 0.943097 | CV16: 0.947668 | CW16: 0.948703 | CX16: 0.946701 | CY16: 0.94581 | CZ16: 0.94926 | DA16: 0.947116 | DB16: 0.951729 | DC16: 0.948359 | DD16: 0.945488 | DE16: 0.947648 | DF16: 0.949499 | DG16: 0.946363 | DH16: 0.946725 | DI16: 0.946796 | DJ16: 0.947617 | DK16: 0.949521 | DL16: 0.940996 | DM16: 0.946003 | DN16: 0.944946 | DO16: 0.94479 | DP16: 0.94728 | DQ16: 0.944153 | DR16: 0.942956 | DS16: 0.939682 | DT16: 0.939078 | DU16: 0.940163 | DV16: 0.940025 | DW16: 0.938851 | DX16: 0.936041 | DY16: 0.936156 | DZ16: 0.937849 | EA16: 0.931825 | EB16: 0.936557 | EC16: 0.940422 | ED16: 0.937779 | EE16: 0.939534 | EF16: 0.939561 | EG16: 0.944194 | EH16: 0.949177 | EI16: 0.946525 | EJ16: 0.94724 | EK16: 0.948709 | EL16: 0.945836 | EM16: 0.951004 | EN16: 0.950042 | EO16: 0.944951 | EP16: 0.944584 | EQ16: 0.928259 | ER16: 0.924559
A17: FR 180 | AD17: 0.957895 | AE17: 0.936295 | AI17: 0.958081 | AJ17: 0.957147 | AL17: 0.959745 | AM17: 0.957525 | AN17: 0.940274 | AO17: 0.939152 | AP17: 0.953095 | AQ17: 0.946262 | AR17: 0.954392 | AS17: 0.952069 | AT17: 0.959678 | AU17: 0.965408 | AV17: 0.953585 | AW17: 0.946404 | AX17: 0.943956 | AY17: 0.932538 | AZ17: 0.943444 | BA17: 0.932418 | BB17: 0.940865 | BC17: 0.970429 | BD17: 0.959632 | BE17: 0.962442 | BF17: 0.948527 | BG17: 0.951852 | BH17: 0.941301 | BI17: 0.962901 | BJ17: 0.951078 | BK17: 0.954773 | BL17: 0.94481 | BM17: 0.946341 | BN17: 0.957169 | BO17: 0.952997 | BP17: 0.956225 | BQ17: 0.956922 | BR17: 0.960296 | BS17: 0.957278 | BT17: 0.952553 | BU17: 0.959533 | BV17: 0.953558 | BW17: 0.952138 | BX17: 0.95326 | BY17: 0.954248 | BZ17: 0.953812 | CA17: 0.950255 | CB17: 0.945894 | CC17: 0.947856 | CD17: 0.950962 | CE17: 0.940782 | CF17: 0.945106 | CG17: 0.93601 | CH17: 0.938316 | CI17: 0.949106 | CJ17: 0.945951 | CK17: 0.946737 | CL17: 0.948204 | CM17: 0.950151 | CN17: 0.947678 | CO17: 0.931072 | CP17: 0.948875 | CQ17: 0.943056 | CR17: 0.938223 | CS17: 0.94658 | CT17: 0.949428 | CU17: 0.945371 | CV17: 0.939379 | CW17: 0.94498 | CX17: 0.945861 | CY17: 0.944056 | CZ17: 0.942329 | DA17: 0.946785 | DB17: 0.9451 | DC17: 0.949298 | DD17: 0.94593 | DE17: 0.943929 | DF17: 0.945622 | DG17: 0.946473 | DH17: 0.943377 | DI17: 0.943369 | DJ17: 0.944101 | DK17: 0.944631 | DL17: 0.946963 | DM17: 0.938244 | DN17: 0.943534 | DO17: 0.942434 | DP17: 0.941404 | DQ17: 0.944724 | DR17: 0.941159 | DS17: 0.939377 | DT17: 0.938077 | DU17: 0.936558 | DV17: 0.936337 | DW17: 0.936298 | DX17: 0.934701 | DY17: 0.932885 | DZ17: 0.933447 | EA17: 0.934615 | EB17: 0.928323 | EC17: 0.934835 | ED17: 0.937268 | EE17: 0.934999 | EF17: 0.936317 | EG17: 0.936572 | EH17: 0.941351 | EI17: 0.947966 | EJ17: 0.944529 | EK17: 0.944453 | EL17: 0.947779 | EM17: 0.945696 | EN17: 0.950601 | EO17: 0.95065 | EP17: 0.941391 | EQ17: 0.942505 | ER17: 0.926983 | ES17: 0.921113
A18: FR GCO | AE18: 0.955718 | AF18: 0.931522 | AJ18: 0.955925 | AK18: 0.954874 | AM18: 0.957737 | AN18: 0.955357 | AO18: 0.936014 | AP18: 0.934731 | AQ18: 0.950416 | AR18: 0.942802 | AS18: 0.951843 | AT18: 0.949299 | AU18: 0.957689 | AV18: 0.963894 | AW18: 0.950967 | AX18: 0.942986 | AY18: 0.940187 | AZ18: 0.927122 | BA18: 0.939664 | BB18: 0.927004 | BC18: 0.936718 | BD18: 0.969348 | BE18: 0.957681 | BF18: 0.960736 | BG18: 0.945392 | BH18: 0.949096 | BI18: 0.937243 | BJ18: 0.961232 | BK18: 0.948264 | BL18: 0.952347 | BM18: 0.941199 | BN18: 0.942959 | BO18: 0.95498 | BP18: 0.950385 | BQ18: 0.953938 | BR18: 0.954691 | BS18: 0.958401 | BT18: 0.95508 | BU18: 0.949867 | BV18: 0.957544 | BW18: 0.950977 | BX18: 0.950236 | BY18: 0.950658 | BZ18: 0.951739 | CA18: 0.953786 | CB18: 0.947313 | CC18: 0.943137 | CD18: 0.946491 | CE18: 0.948088 | CF18: 0.936643 | CG18: 0.941534 | CH18: 0.935048 | CI18: 0.933822 | CJ18: 0.946029 | CK18: 0.94249 | CL18: 0.943873 | CM18: 0.94581 | CN18: 0.947187 | CO18: 0.944427 | CP18: 0.932424 | CQ18: 0.945872 | CR18: 0.93921 | CS18: 0.934755 | CT18: 0.94458 | CU18: 0.946669 | CV18: 0.942171 | CW18: 0.935811 | CX18: 0.942037 | CY18: 0.942835 | CZ18: 0.941103 | DA18: 0.940069 | DB18: 0.943427 | DC18: 0.943791 | DD18: 0.947481 | DE18: 0.943971 | DF18: 0.940764 | DG18: 0.943089 | DH18: 0.94409 | DI18: 0.939601 | DJ18: 0.940139 | DK18: 0.941474 | DL18: 0.942189 | DM18: 0.94464 | DN18: 0.935108 | DO18: 0.940357 | DP18: 0.939501 | DQ18: 0.938557 | DR18: 0.942994 | DS18: 0.937429 | DT18: 0.936267 | DU18: 0.935092 | DV18: 0.932152 | DW18: 0.933355 | DX18: 0.932992 | DY18: 0.930151 | DZ18: 0.929481 | EA18: 0.930586 | EB18: 0.931839 | EC18: 0.926241 | ED18: 0.931693 | EE18: 0.935056 | EF18: 0.93124 | EG18: 0.933012 | EH18: 0.933861 | EI18: 0.939869 | EJ18: 0.945979 | EK18: 0.942939 | EL18: 0.942633 | EM18: 0.946423 | EN18: 0.94511 | EO18: 0.949787 | EP18: 0.948802 | EQ18: 0.941635 | ER18: 0.940864 | ES18: 0.92077 | ET18: 0.916183
A20: Grade A - FTR Diagonal
A21: FTR | Y21: 0.00328388 | Z21: 0.00034386 | AD21: 0.00188825 | AE21: 0.00102307 | AG21: 0.00278924 | AH21: 0.00077916 | AI21: 0.00055026 | AJ21: 0.00441165 | AK21: 0.00158999 | AL21: 0.00070696 | AM21: 0.00035089 | AN21: 0.00113276 | AO21: 0.00117407 | AP21: 0.00052388 | AQ21: 0.00039657 | AR21: 0.00065951 | AS21: 0.0008463 | AT21: 0.00025745 | AU21: 0.00102949 | AV21: 0.00064059 | AW21: 0.00095824 | AX21: 0.00064627 | AY21: 0.00052169 | AZ21: 0.00116187 | BA21: 0.00164559 | BB21: 0.00078693 | BC21: 0.00082327 | BD21: 0.00089587 | BE21: 0.000549 | BF21: 0.00051674 | BG21: 0.00075778 | BH21: 0.00075595 | BI21: 0.00148137 | BJ21: 0.00124742 | BK21: 0.00102418 | BL21: 0.00146138 | BM21: 0.00172901 | BN21: 0.00117561 | BO21: 0.00175725 | BP21: 0.00138292 | BQ21: 0.00128498 | BR21: 0.00153206 | BS21: 0.00136189 | BT21: 0.0013542 | BU21: 0.00115157 | BV21: 0.00080242 | BW21: 0.00101373 | BX21: 0.00101451 | BY21: 0.00130238 | BZ21: 0.00086096 | CA21: 0.00099228 | CB21: 0.00054829 | CC21: 0.00077649 | CD21: 0.00085008 | CE21: 0.00049527 | CF21: 0.00066467 | CG21: 0.00074657 | CH21: 0.00064781 | CI21: 0.00092494 | CJ21: 0.00070226 | CK21: 0.00080109 | CL21: 0.00072358 | CM21: 0.00074432 | CN21: 0.00055018 | CO21: 0.00093833 | CP21: 0.00072679 | CQ21: 0.00077145 | CR21: 0.00083781 | CS21: 0.00088849 | CT21: 0.00070954 | CU21: 0.0007149 | CV21: 0.00098722 | CW21: 0.00085856 | CX21: 0.00085482 | CY21: 0.00087985 | CZ21: 0.00059459 | DA21: 0.00087502 | DB21: 0.00089026 | DC21: 0.00065577 | DD21: 0.00094527 | DE21: 0.00089624 | DF21: 0.00085636 | DG21: 0.00132895 | DH21: 0.00102918 | DI21: 0.00133795 | DJ21: 0.00160855 | DK21: 0.00152274 | DL21: 0.00145624 | DM21: 0.00153203 | DN21: 0.00186818 | DO21: 0.0014734 | DP21: 0.00176006 | DQ21: 0.00202667 | DR21: 0.00187677 | DS21: 0.00195902 | DT21: 0.00191112 | DU21: 0.00234169 | DV21: 0.0019678 | DW21: 0.00223702 | DX21: 0.00239129 | DY21: 0.00266509 | DZ21: 0.00278752 | EA21: 0.00252378 | EB21: 0.00374196 | EC21: 0.00391249 | ED21: 0.00462398 | EE21: 0.0053545 | EF21: 0.00670013 | EG21: 0.00879534 | EH21: 0.00786781 | EI21: 0.01361984 | EJ21: 0.00559282 | EK21: 0.00312664 | EL21: 0.00449699 | EM21: 0.00267921 | EN21: 0.00613176
A23: Grade A - Loss Metrics
A24: GCO | C24: 0 | D24: 0 | E24: 0 | F24: 0 | G24: 0 | H24: 0 | I24: 0 | J24: 0 | K24: 0 | L24: 0 | M24: 0 | N24: 0 | O24: 0 | P24: 0 | Q24: 0 | R24: 0 | S24: 0 | T24: 0 | U24: 0 | V24: 0 | W24: 0 | X24: 0 | Y24: 0 | Z24: 0 | AA24: 0 | AB24: 0 | AC24: 0 | AD24: 0 | AE24: 10844.98 | AF24: 1261.34 | AG24: 660.98 | AH24: 0 | AI24: 0 | AJ24: 11482.55 | AK24: 6918.97 | AL24: 0 | AM24: 23112.29 | AN24: 7005.1 | AO24: 5304.78 | AP24: 45946.5 | AQ24: 17647.71 | AR24: 8673.27 | AS24: 4762.79 | AT24: 17105.33 | AU24: 18714.99 | AV24: 9008.09 | AW24: 7622.6 | AX24: 13934.47 | AY24: 20297.6 | AZ24: 6812.14 | BA24: 28949.12 | BB24: 19062.57 | BC24: 29801.59 | BD24: 21267.25 | BE24: 18307.17 | BF24: 43386.02 | BG24: 66885.25 | BH24: 35439.12 | BI24: 41116.75 | BJ24: 48290.65 | BK24: 30993.72 | BL24: 31792.55 | BM24: 51274.95 | BN24: 56101.19 | BO24: 117923.2 | BP24: 106649.33 | BQ24: 91496.15 | BR24: 137489.76 | BS24: 175589.45 | BT24: 127602.1 | BU24: 202123.09 | BV24: 165911.22 | BW24: 167945.47 | BX24: 215373.62 | BY24: 207795.28 | BZ24: 227759.05 | CA24: 209703.08 | CB24: 152969.26 | CC24: 202287.43 | CD24: 213859.21 | CE24: 288092.14 | CF24: 198637.42 | CG24: 243179.02 | CH24: 149083.81 | CI24: 230052.06 | CJ24: 271037.21 | CK24: 167344 | CL24: 235194.37 | CM24: 280949.27 | CN24: 257417.95 | CO24: 380383.57 | CP24: 312245.51 | CQ24: 374379.72 | CR24: 344162.96 | CS24: 411049.88 | CT24: 320398.01 | CU24: 549246.37 | CV24: 468852.71 | CW24: 522771.43 | CX24: 592041.72 | CY24: 673876.41 | CZ24: 571049.55 | DA24: 598415.25 | DB24: 895510.72 | DC24: 814298.58 | DD24: 832548.54 | DE24: 926725.14 | DF24: 651387.23 | DG24: 1007944.7 | DH24: 1058373.3 | DI24: 808534.33 | DJ24: 1261265 | DK24: 1200275.7 | DL24: 1132437.6 | DM24: 1740864.5 | DN24: 1307167.1 | DO24: 1643128.8 | DP24: 1896809.2 | DQ24: 1731624.5 | DR24: 1592681.8 | DS24: 1612339.7 | DT24: 1888311.8 | DU24: 1422513.9 | DV24: 1640382.2 | DW24: 1790982 | DX24: 1594160.3 | DY24: 1593590.9 | DZ24: 1477115 | EA24: 1725067.1 | EB24: 1367697.6 | EC24: 1479878.3 | ED24: 1510497.8 | EE24: 1590639.6 | EF24: 1576126.8 | EG24: 1321797.3 | EH24: 1824013.7 | EI24: 1736698 | EJ24: 1889358.9 | EK24: 1983230.2 | EL24: 2215922.7 | EM24: 2542491.5 | EN24: 1928744.1 | EO24: 2838176.8 | EP24: 930035.98 | EQ24: 404346.98 | ER24: 419475.03 | ES24: 148103.06 | ET24: 103018.37 | EU24: 0 | EV24: 0 | EW24: 0 | EX24: 0 | EY24: 0 | EZ24: 0 | FA24: 0 | FB24: 0 | FC24: 0 | FD24: 0 | FE24: 0 | FF24: 0 | FG24: 0 | FH24: 0 | FI24: 0 | FJ24: 0 | FK24: 0 | FL24: 0 | FM24: 0 | FN24: 0 | FO24: 0 | FP24: 0 | FQ24: 0 | FR24: 0 | FS24: 0 | FT24: 0 | FU24: 0 | FV24: 0 | FW24: 0 | FX24: 0 | FY24: 0 | FZ24: 0 | GA24: 0 | GB24: 0 | GC24: 0 | GD24: 0 | GE24: 0 | GF24: 0 | GG24: 0 | GH24: 0 | GI24: 0 | GJ24: 0 | GK24: 0 | GL24: 0 | GM24: 0 | GN24: 0 | GO24: 0
A25: Recovery | C25: 0 | D25: 0 | E25: 0 | F25: 0 | G25: 0 | H25: 0 | I25: 0 | J25: 0 | K25: 0 | L25: 0 | M25: 0 | N25: 0 | O25: 0 | P25: 0 | Q25: 0 | R25: 0 | S25: 0 | T25: 0 | U25: 0 | V25: 0 | W25: 0 | X25: 0 | Y25: 0 | Z25: 0 | AA25: 0 | AB25: 0 | AC25: 0 | AD25: 0 | AE25: 0 | AF25: 0 | AG25: 0 | AH25: 0 | AI25: 0 | AJ25: 0 | AK25: 3725.14 | AL25: 1351.31 | AM25: 886.3 | AN25: 0 | AO25: 0 | AP25: 4134.88 | AQ25: 1986.19 | AR25: 0 | AS25: 7214.5 | AT25: 2510.75 | AU25: 4746.95 | AV25: 38021.12 | AW25: 7449.54 | AX25: 5441.29 | AY25: 2210.47 | AZ25: 9101.78 | BA25: 4309.24 | BB25: 3184.72 | BC25: 10231.7 | BD25: 9253.39 | BE25: 12864.63 | BF25: 6884.48 | BG25: 22382.06 | BH25: 25897.92 | BI25: 26111.77 | BJ25: 3987.61 | BK25: 7275.44 | BL25: 12994.64 | BM25: 43316.84 | BN25: 30251 | BO25: 44155.35 | BP25: 8694.06 | BQ25: 18494.03 | BR25: 16171.54 | BS25: 35799.11 | BT25: 46874.39 | BU25: 44560.35 | BV25: 59448.91 | BW25: 56537.25 | BX25: 58459.17 | BY25: 55426.37 | BZ25: 64316.32 | CA25: 109610.75 | CB25: 63911 | CC25: 81575.04 | CD25: 128852.59 | CE25: 111589.62 | CF25: 120841.81 | CG25: 120830.6 | CH25: 107248.62 | CI25: 153582.79 | CJ25: 156900.14 | CK25: 174759.69 | CL25: 198213.19 | CM25: 207444.1 | CN25: 184722.05 | CO25: 220996.07 | CP25: 244066.11 | CQ25: 153779.94 | CR25: 204083.99 | CS25: 232432.48 | CT25: 169638.26 | CU25: 292065.56 | CV25: 409527.67 | CW25: 241468.36 | CX25: 293179.83 | CY25: 468390.81 | CZ25: 284413.67 | DA25: 452506.36 | DB25: 398733.02 | DC25: 508935.66 | DD25: 524157.23 | DE25: 539743.78 | DF25: 525833.55 | DG25: 629097.85 | DH25: 751089.59 | DI25: 716611.88 | DJ25: 612928.75 | DK25: 780302.66 | DL25: 615279.15 | DM25: 862203.59 | DN25: 908759.38 | DO25: 728718.91 | DP25: 1085852.6 | DQ25: 1049289.2 | DR25: 991588.73 | DS25: 1475848.7 | DT25: 1508395.4 | DU25: 1550235.3 | DV25: 1956470 | DW25: 1860309.1 | DX25: 1466829.6 | DY25: 1661007.5 | DZ25: 2027991.5 | EA25: 1710691.4 | EB25: 2098553.4 | EC25: 2151318.5 | ED25: 1978047.6 | EE25: 2118831.4 | EF25: 2054295.7 | EG25: 2440334.6 | EH25: 1867175 | EI25: 2394728.3 | EJ25: 2114982.8 | EK25: 1971378.6 | EL25: 2261000.5 | EM25: 1796790.2 | EN25: 2346835.7 | EO25: 2076523.5 | EP25: 1853362.1 | EQ25: 2245167.4 | ER25: 2385038 | ES25: 2497399.4 | ET25: 2133517.6 | EU25: 2491591.2 | EV25: 1044631.6 | EW25: 729064.62 | EX25: 599174.8 | EY25: 255014.55 | EZ25: 378117.14 | FA25: 0 | FB25: 0 | FC25: 0 | FD25: 0 | FE25: 0 | FF25: 0 | FG25: 0 | FH25: 0 | FI25: 0 | FJ25: 0 | FK25: 0 | FL25: 0 | FM25: 0 | FN25: 0 | FO25: 0 | FP25: 0 | FQ25: 0 | FR25: 0 | FS25: 0 | FT25: 0 | FU25: 0 | FV25: 0 | FW25: 0 | FX25: 0 | FY25: 0 | FZ25: 0 | GA25: 0 | GB25: 0 | GC25: 0 | GD25: 0 | GE25: 0 | GF25: 0 | GG25: 0 | GH25: 0 | GI25: 0 | GJ25: 0 | GK25: 0 | GL25: 0 | GM25: 0 | GN25: 0 | GO25: 0
A26: NCO | C26: 0 | D26: 0 | E26: 0 | F26: 0 | G26: 0 | H26: 0 | I26: 0 | J26: 0 | K26: 0 | L26: 0 | M26: 0 | N26: 0 | O26: 0 | P26: 0 | Q26: 0 | R26: 0 | S26: 0 | T26: 0 | U26: 0 | V26: 0 | W26: 0 | X26: 0 | Y26: 0 | Z26: 0 | AA26: 0 | AB26: 0 | AC26: 0 | AD26: 0 | AE26: 10844.98 | AF26: 1261.34 | AG26: 660.98 | AH26: 0 | AI26: 0 | AJ26: 11482.55 | AK26: 3193.83 | AL26: -1351.31 | AM26: 22225.99 | AN26: 7005.1 | AO26: 5304.78 | AP26: 41811.62 | AQ26: 15661.52 | AR26: 8673.27 | AS26: -2451.71 | AT26: 14594.58 | AU26: 13968.04 | AV26: -29013.03 | AW26: 173.06 | AX26: 8493.18 | AY26: 18087.13 | AZ26: -2289.64 | BA26: 24639.88 | BB26: 15877.85 | BC26: 19569.89 | BD26: 12013.86 | BE26: 5442.54 | BF26: 36501.54 | BG26: 44503.19 | BH26: 9541.2 | BI26: 15004.98 | BJ26: 44303.04 | BK26: 23718.28 | BL26: 18797.91 | BM26: 7958.11 | BN26: 25850.19 | BO26: 73767.85 | BP26: 97955.27 | BQ26: 73002.12 | BR26: 121318.22 | BS26: 139790.34 | BT26: 80727.71 | BU26: 157562.74 | BV26: 106462.31 | BW26: 111408.22 | BX26: 156914.45 | BY26: 152368.91 | BZ26: 163442.73 | CA26: 100092.33 | CB26: 89058.26 | CC26: 120712.39 | CD26: 85006.62 | CE26: 176502.52 | CF26: 77795.61 | CG26: 122348.42 | CH26: 41835.19 | CI26: 76469.27 | CJ26: 114137.07 | CK26: -7415.69 | CL26: 36981.18 | CM26: 73505.17 | CN26: 72695.9 | CO26: 159387.5 | CP26: 68179.4 | CQ26: 220599.78 | CR26: 140078.97 | CS26: 178617.4 | CT26: 150759.75 | CU26: 257180.81 | CV26: 59325.04 | CW26: 281303.07 | CX26: 298861.89 | CY26: 205485.6 | CZ26: 286635.88 | DA26: 145908.89 | DB26: 496777.7 | DC26: 305362.92 | DD26: 308391.31 | DE26: 386981.36 | DF26: 125553.68 | DG26: 378846.84 | DH26: 307283.75 | DI26: 91922.45 | DJ26: 648336.21 | DK26: 419973.04 | DL26: 517158.46 | DM26: 878660.93 | DN26: 398407.73 | DO26: 914409.93 | DP26: 810956.64 | DQ26: 682335.25 | DR26: 601093.09 | DS26: 136491.03 | DT26: 379916.36 | DU26: -127721.43 | DV26: -316087.77 | DW26: -69327.05 | DX26: 127330.63 | DY26: -67416.6 | DZ26: -550876.44 | EA26: 14375.71 | EB26: -730855.73 | EC26: -671440.27 | ED26: -467549.83 | EE26: -528191.82 | EF26: -478168.89 | EG26: -1118537.3 | EH26: -43161.36 | EI26: -658030.26 | EJ26: -225623.88 | EK26: 11851.57 | EL26: -45077.83 | EM26: 745701.29 | EN26: -418091.67 | EO26: 761653.27 | EP26: -923326.09 | EQ26: -1840820.4 | ER26: -1965563 | ES26: -2349296.4 | ET26: -2030499.2 | EU26: -2491591.2 | EV26: -1044631.6 | EW26: -729064.62 | EX26: -599174.8 | EY26: -255014.55 | EZ26: -378117.14 | FA26: 0 | FB26: 0 | FC26: 0 | FD26: 0 | FE26: 0 | FF26: 0 | FG26: 0 | FH26: 0 | FI26: 0 | FJ26: 0 | FK26: 0 | FL26: 0 | FM26: 0 | FN26: 0 | FO26: 0 | FP26: 0 | FQ26: 0 | FR26: 0 | FS26: 0 | FT26: 0 | FU26: 0 | FV26: 0 | FW26: 0 | FX26: 0 | FY26: 0 | FZ26: 0 | GA26: 0 | GB26: 0 | GC26: 0 | GD26: 0 | GE26: 0 | GF26: 0 | GG26: 0 | GH26: 0 | GI26: 0 | GJ26: 0 | GK26: 0 | GL26: 0 | GM26: 0 | GN26: 0 | GO26: 0
A27: Loss Rate | C27: 0 | D27: 0 | E27: 0 | F27: 0 | G27: 0 | H27: 0 | I27: 0 | J27: 0 | K27: 0 | L27: 0 | M27: 0 | N27: 0 | O27: 0 | P27: 0 | Q27: 0 | R27: 0 | S27: 0 | T27: 0 | U27: 0 | V27: 0 | W27: 0 | X27: 0 | Y27: 0 | Z27: 0 | AA27: 0 | AB27: 0 | AC27: 0 | AD27: 0 | AE27: 0.0014 | AF27: 0.0002 | AG27: 0.0001 | AH27: 0 | AI27: 0 | AJ27: 0.001 | AK27: 0.0003 | AL27: -0.0001 | AM27: 0.0015 | AN27: 0.0004 | AO27: 0.0003 | AP27: 0.0022 | AQ27: 0.0007 | AR27: 0.0004 | AS27: -0.0001 | AT27: 0.0005 | AU27: 0.0005 | AV27: -0.0009 | AW27: 0 | AX27: 0.0002 | AY27: 0.0005 | AZ27: -0.0001 | BA27: 0.0005 | BB27: 0.0003 | BC27: 0.0004 | BD27: 0.0002 | BE27: 0.0001 | BF27: 0.0005 | BG27: 0.0006 | BH27: 0.0001 | BI27: 0.0002 | BJ27: 0.0005 | BK27: 0.0003 | BL27: 0.0002 | BM27: 0.0001 | BN27: 0.0002 | BO27: 0.0006 | BP27: 0.0007 | BQ27: 0.0005 | BR27: 0.0008 | BS27: 0.0008 | BT27: 0.0004 | BU27: 0.0008 | BV27: 0.0005 | BW27: 0.0005 | BX27: 0.0007 | BY27: 0.0007 | BZ27: 0.0007 | CA27: 0.0004 | CB27: 0.0003 | CC27: 0.0004 | CD27: 0.0003 | CE27: 0.0005 | CF27: 0.0002 | CG27: 0.0003 | CH27: 0.0001 | CI27: 0.0002 | CJ27: 0.0002 | CK27: 0 | CL27: 0.0001 | CM27: 0.0001 | CN27: 0.0001 | CO27: 0.0002 | CP27: 0.0001 | CQ27: 0.0003 | CR27: 0.0002 | CS27: 0.0002 | CT27: 0.0002 | CU27: 0.0003 | CV27: 0.0001 | CW27: 0.0003 | CX27: 0.0003 | CY27: 0.0002 | CZ27: 0.0002 | DA27: 0.0001 | DB27: 0.0004 | DC27: 0.0002 | DD27: 0.0002 | DE27: 0.0003 | DF27: 0.0001 | DG27: 0.0003 | DH27: 0.0002 | DI27: 0.0001 | DJ27: 0.0006 | DK27: 0.0004 | DL27: 0.0005 | DM27: 0.0009 | DN27: 0.0004 | DO27: 0.001 | DP27: 0.0009 | DQ27: 0.0008 | DR27: 0.0007 | DS27: 0.0002 | DT27: 0.0005 | DU27: -0.0002 | DV27: -0.0005 | DW27: -0.0001 | DX27: 0.0002 | DY27: -0.0001 | DZ27: -0.001 | EA27: 0 | EB27: -0.0016 | EC27: -0.0016 | ED27: -0.0012 | EE27: -0.0015 | EF27: -0.0016 | EG27: -0.0043 | EH27: -0.0002 | EI27: -0.0036 | EJ27: -0.0016 | EK27: 0.0001 | EL27: -0.0007 | EM27: 0.0306 | EN27: -0.0652 | EO27: 0.2344 | EP27: -0.43 | EQ27: -1.1323 | ER27: -1.762 | ES27: -2.5992 | ET27: -2.7061 | EU27: -3.5141 | EV27: -1.564 | EW27: -1.162 | EX27: -1.0197 | EY27: -0.4657 | EZ27: -0.7431 | FA27: 0 | FB27: 0 | FC27: 0 | FD27: 0 | FE27: 0 | FF27: 0 | FG27: 0 | FH27: 0 | FI27: 0 | FJ27: 0 | FK27: 0 | FL27: 0 | FM27: 0 | FN27: 0 | FO27: 0 | FP27: 0 | FQ27: 0 | FR27: 0 | FS27: 0 | FT27: 0 | FU27: 0 | FV27: 0 | FW27: 0 | FX27: 0 | FY27: 0 | FZ27: 0 | GA27: 0 | GB27: 0 | GC27: 0 | GD27: 0 | GE27: 0 | GF27: 0 | GG27: 0 | GH27: 0 | GI27: 0 | GJ27: 0 | GK27: 0 | GL27: 0 | GM27: 0 | GN27: 0 | GO27: 0
A29: Grade A - DCF-ECL
A30: ECL Reserve (DCF-ECL) | C30: -457.06 | D30: -742.78 | E30: -908.84 | F30: -1173.99 | G30: -1552.84 | H30: -1830.53 | I30: -3618.03 | J30: -4648.24 | K30: -5647.8 | L30: -6035.39 | M30: -6095.18 | N30: -5958.19 | O30: -6096.03 | P30: -5647.2 | Q30: -5194.85 | R30: -5357.87 | S30: -5953.89 | T30: -7541.29 | U30: -9600.51 | V30: -11303.14 | W30: -13555.86 | X30: -16334.98 | Y30: -17846.14 | Z30: -20300.63 | AA30: -22374.85 | AB30: -25045.27 | AC30: -28348.59 | AD30: -30923.79 | AE30: -33820.09 | AF30: -36619.81 | AG30: -39130.85 | AH30: -40717.65 | AI30: -43577.6 | AJ30: -45730.42 | AK30: -51211 | AL30: -56852.1 | AM30: -63557.82 | AN30: -65054.22 | AO30: -68856.1 | AP30: -80007.32 | AQ30: -88994.73 | AR30: -102345.29 | AS30: -114470.91 | AT30: -118608.75 | AU30: -122797.85 | AV30: -123975.55 | AW30: -127331.59 | AX30: -132428.76 | AY30: -136931.25 | AZ30: -148315.42 | BA30: -166365.77 | BB30: -186999.82 | BC30: -199648 | BD30: -201186.54 | BE30: -220351.42 | BF30: -245004.96 | BG30: -273152.04 | BH30: -290386.99 | BI30: -308746.45 | BJ30: -311006.19 | BK30: -318010.92 | BL30: -343665.76 | BM30: -364452.11 | BN30: -378087.68 | BO30: -380235.55 | BP30: -419476.15 | BQ30: -449393.4 | BR30: -493730.05 | BS30: -559448.58 | BT30: -612068.68 | BU30: -617320.37 | BV30: -626593.28 | BW30: -649607.12 | BX30: -662657.93 | BY30: -666941.06 | BZ30: -700176.64 | CA30: -821355.27 | CB30: -922980.53 | CC30: -1048315 | CD30: -1131212.8 | CE30: -1180217.4 | CF30: -1278698.4 | CG30: -1354449.1 | CH30: -1369372.8 | CI30: -1544908.3 | CJ30: -1623466.1 | CK30: -1592465.5 | CL30: -2229409.4 | CM30: -2360489.5 | CN30: -2206506.5 | CO30: -2592302.2 | CP30: -2725861.5 | CQ30: -2810188.8 | CR30: -3098203 | CS30: -3317175.6 | CT30: -3367459.2 | CU30: -3767189.1 | CV30: -3893418 | CW30: -3842273.2 | CX30: -4261771 | CY30: -4323634.1 | CZ30: -4490716.7 | DA30: -6086214.6 | DB30: -7725522.5 | DC30: -11225076 | DD30: -11782036 | DE30: -11533060 | DF30: -11149806 | DG30: -9968937.4 | DH30: -8754030 | DI30: -7406774.7 | DJ30: -6288052.8 | DK30: -5268731.2 | DL30: -4318212.3 | DM30: -3438774.3 | DN30: -2479383.2 | DO30: -1779907.6 | DP30: -925938.95 | DQ30: -213207.74 | DR30: 527785.29 | DS30: 1211216.8 | DT30: 1879426.1 | DU30: 2732962.7 | DV30: 2986355.9 | DW30: 3377692.8 | DX30: 4136490.2 | DY30: 4417925.8 | DZ30: 5009856.3 | EA30: 5542749.8 | EB30: 5929197.4 | EC30: 6284238.6 | ED30: 6800914.3 | EE30: 7023117.2 | EF30: 7416757.8 | EG30: 7946562.6 | EH30: 8071211.5 | EI30: 8442907 | EJ30: 8656286.5 | EK30: 8297871.4 | EL30: 7717578.6 | EM30: 6195956.7 | EN30: 5891947.8 | EO30: 5894068.9 | EP30: 5743937.3 | EQ30: 5875751.1 | ER30: 6001696.6 | ES30: 6167537.4 | ET30: 6150396.5 | EU30: 6144585.3 | EV30: 6097922.9 | EW30: 5991471.4 | EX30: 5911846.6 | EY30: 5670453.6 | EZ30: 5520363.4 | FA30: 5257606.4 | FB30: 4966322.3 | FC30: 4685088.8 | FD30: 4368004.8 | FE30: 4120674.5 | FF30: 3784585.3 | FG30: 3382626.4 | FH30: 3049747.3 | FI30: 2693481 | FJ30: 2409942.6 | FK30: 1995008.3 | FL30: 1670117.4 | FM30: 1336537.9 | FN30: 1081461.3 | FO30: 891330.9 | FP30: 732169.89 | FQ30: 604391.56 | FR30: 501811.88 | FS30: 429498.62 | FT30: 365347.64 | FU30: 353320.39 | FV30: 341989.9 | FW30: 326340.32 | FX30: 310931.54 | FY30: 297771.46 | FZ30: 285636.52 | GA30: 275735.16 | GB30: 264810.39 | GC30: 247837.16 | GD30: 230194.67 | GE30: 205463.04 | GF30: 184943.75 | GG30: 163558.56 | GH30: 144947.67 | GI30: 125295.68 | GJ30: 107651.71 | GK30: 90000.47 | GL30: 74798.12 | GM30: 56432.46 | GN30: 39355.14 | GO30: 25062.14
A31: ALLL Ratio (DCF-ECL) | C31: -0.007136 | D31: -0.006912 | E31: -0.00667 | F31: -0.006506 | G31: -0.006399 | H31: -0.006223 | I31: -0.006498 | J31: -0.006425 | K31: -0.006244 | L31: -0.006073 | M31: -0.005961 | N31: -0.005721 | O31: -0.00546 | P31: -0.005041 | Q31: -0.00464 | R31: -0.004447 | S31: -0.004448 | T31: -0.004597 | U31: -0.004771 | V31: -0.004793 | W31: -0.004862 | X31: -0.004946 | Y31: -0.004847 | Z31: -0.004805 | AA31: -0.00471 | AB31: -0.004663 | AC31: -0.004651 | AD31: -0.004554 | AE31: -0.004488 | AF31: -0.004407 | AG31: -0.004328 | AH31: -0.004199 | AI31: -0.004159 | AJ31: -0.004078 | AK31: -0.004132 | AL31: -0.004149 | AM31: -0.004179 | AN31: -0.004051 | AO31: -0.003974 | AP31: -0.004143 | AQ31: -0.004197 | AR31: -0.004252 | AS31: -0.004309 | AT31: -0.004204 | AU31: -0.004112 | AV31: -0.003971 | AW31: -0.003852 | AX31: -0.003757 | AY31: -0.003652 | AZ31: -0.003632 | BA31: -0.003675 | BB31: -0.003725 | BC31: -0.003685 | BD31: -0.003545 | BE31: -0.003563 | BF31: -0.003605 | BG31: -0.003667 | BH31: -0.003634 | BI31: -0.003594 | BJ31: -0.003463 | BK31: -0.003361 | BL31: -0.003362 | BM31: -0.003333 | BN31: -0.003262 | BO31: -0.003143 | BP31: -0.003184 | BQ31: -0.003171 | BR31: -0.00321 | BS31: -0.003301 | BT31: -0.003335 | BU31: -0.003214 | BV31: -0.003118 | BW31: -0.003061 | BX31: -0.002976 | BY31: -0.002871 | BZ31: -0.002839 | CA31: -0.003003 | CB31: -0.003099 | CC31: -0.003271 | CD31: -0.003331 | CE31: -0.003321 | CF31: -0.003384 | CG31: -0.003395 | CH31: -0.003316 | CI31: -0.003459 | CJ31: -0.003459 | CK31: -0.003332 | CL31: -0.00402 | CM31: -0.004036 | CN31: -0.003753 | CO31: -0.004001 | CP31: -0.004005 | CQ31: -0.003959 | CR31: -0.004066 | CS31: -0.004102 | CT31: -0.004003 | CU31: -0.004134 | CV31: -0.004085 | CW31: -0.003925 | CX31: -0.004026 | CY31: -0.003926 | CZ31: -0.003879 | DA31: -0.005093 | DB31: -0.006233 | DC31: -0.008372 | DD31: -0.008752 | DE31: -0.008673 | DF31: -0.00846 | DG31: -0.007794 | DH31: -0.007075 | DI31: -0.006227 | DJ31: -0.005476 | DK31: -0.004766 | DL31: -0.004056 | DM31: -0.003362 | DN31: -0.002535 | DO31: -0.001885 | DP31: -0.001033 | DQ31: -0.000247 | DR31: 0.000639 | DS31: 0.001542 | DT31: 0.00251 | DU31: 0.003863 | DV31: 0.004434 | DW31: 0.00525 | DX31: 0.006798 | DY31: 0.007656 | DZ31: 0.009356 | EA31: 0.011116 | EB31: 0.013013 | EC31: 0.014941 | ED31: 0.017769 | EE31: 0.020442 | EF31: 0.024505 | EG31: 0.030548 | EH31: 0.036125 | EI31: 0.046232 | EJ31: 0.060026 | EK31: 0.07828 | EL31: 0.117449 | EM31: 0.254244 | EN31: 0.918596 | EO31: 1.813578 | EP31: 2.674757 | EQ31: 3.614303 | ER31: 5.38023 | ES31: 6.823688 | ET31: 8.196869 | EU31: 8.666231 | EV31: 9.129515 | EW31: 9.549434 | EX31: 10.061063 | EY31: 10.356225 | EZ31: 10.849533 | FA31: 11.163454 | FB31: 11.438025 | FC31: 11.739905 | FD31: 12.001221 | FE31: 12.479776 | FF31: 12.730024 | FG31: 12.748406 | FH31: 13.055729 | FI31: 13.129943 | FJ31: 13.27643 | FK31: 12.586021 | FL31: 12.055976 | FM31: 10.939303 | FN31: 10.075743 | FO31: 9.257901 | FP31: 8.563666 | FQ31: 7.879492 | FR31: 7.19013 | FS31: 6.544346 | FT31: 5.915895 | FU31: 6.080634 | FV31: 6.282911 | FW31: 6.43231 | FX31: 6.613586 | FY31: 6.881682 | FZ31: 7.230812 | GA31: 7.721184 | GB31: 8.302185 | GC31: 8.833215 | GD31: 9.514459 | GE31: 10.118014 | GF31: 10.958405 | GG31: 12.182504 | GH31: 14.563293 | GI31: 16.322023 | GJ31: 18.506948 | GK31: 18.97209 | GL31: 20.415261 | GM31: 21.900419 | GN31: 26.544398 | GO31: 65.726927
